[2019-01-27 23:43:53] [main] INFO  SolrRddSpark$:18 - Scallop(--field, raw, --term, event, --rows, 1000, --solr, 192.168.1.111:9983, --index, cw09b, --task, sleep, --duration, 3)
 *  term => event
 *  task => sleep
 *  duration => 3
    debug => false
 *  solr => 192.168.1.111:9983
 *  index => cw09b
 *  field => raw
 *  rows => 1000
    parallelism => 12

[2019-01-27 23:43:53] [main] INFO  SparkContext:54 - Running Spark version 2.4.0
[2019-01-27 23:43:53] [main] INFO  SparkContext:54 - Submitted application: SolrRddSpark$
[2019-01-27 23:43:53] [main] INFO  SecurityManager:54 - Changing view acls to: zakkalyo
[2019-01-27 23:43:53] [main] INFO  SecurityManager:54 - Changing modify acls to: zakkalyo
[2019-01-27 23:43:53] [main] INFO  SecurityManager:54 - Changing view acls groups to: 
[2019-01-27 23:43:53] [main] INFO  SecurityManager:54 - Changing modify acls groups to: 
[2019-01-27 23:43:53] [main] INFO  SecurityManager:54 - SecurityManager: authentication disabled; ui acls disabled; users  with view permissions: Set(zakkalyo); groups with view permissions: Set(); users  with modify permissions: Set(zakkalyo); groups with modify permissions: Set()
[2019-01-27 23:43:54] [main] INFO  Utils:54 - Successfully started service 'sparkDriver' on port 44012.
[2019-01-27 23:43:54] [main] INFO  SparkEnv:54 - Registering MapOutputTracker
[2019-01-27 23:43:54] [main] INFO  SparkEnv:54 - Registering BlockManagerMaster
[2019-01-27 23:43:54] [main] INFO  BlockManagerMasterEndpoint:54 - Using org.apache.spark.storage.DefaultTopologyMapper for getting topology information
[2019-01-27 23:43:54] [main] INFO  BlockManagerMasterEndpoint:54 - BlockManagerMasterEndpoint up
[2019-01-27 23:43:54] [main] INFO  DiskBlockManager:54 - Created local directory at /tmp/blockmgr-babdef37-8b10-4212-adb9-426c73854085
[2019-01-27 23:43:54] [main] INFO  MemoryStore:54 - MemoryStore started with capacity 16.9 GB
[2019-01-27 23:43:54] [main] INFO  SparkEnv:54 - Registering OutputCommitCoordinator
[2019-01-27 23:43:54] [main] INFO  log:192 - Logging initialized @4087ms
[2019-01-27 23:43:54] [main] INFO  Server:351 - jetty-9.3.z-SNAPSHOT, build timestamp: unknown, git hash: unknown
[2019-01-27 23:43:54] [main] INFO  Server:419 - Started @4257ms
[2019-01-27 23:43:54] [main] INFO  AbstractConnector:278 - Started ServerConnector@2bfeb1ef{HTTP/1.1,[http/1.1]}{0.0.0.0:4040}
[2019-01-27 23:43:54] [main] INFO  Utils:54 - Successfully started service 'SparkUI' on port 4040.
[2019-01-27 23:43:54] [main] INFO  ContextHandler:781 - Started o.s.j.s.ServletContextHandler@5b56b654{/jobs,null,AVAILABLE,@Spark}
[2019-01-27 23:43:54] [main] INFO  ContextHandler:781 - Started o.s.j.s.ServletContextHandler@5f8890c2{/jobs/json,null,AVAILABLE,@Spark}
[2019-01-27 23:43:54] [main] INFO  ContextHandler:781 - Started o.s.j.s.ServletContextHandler@607b2792{/jobs/job,null,AVAILABLE,@Spark}
[2019-01-27 23:43:54] [main] INFO  ContextHandler:781 - Started o.s.j.s.ServletContextHandler@138a7441{/jobs/job/json,null,AVAILABLE,@Spark}
[2019-01-27 23:43:54] [main] INFO  ContextHandler:781 - Started o.s.j.s.ServletContextHandler@81ff872{/stages,null,AVAILABLE,@Spark}
[2019-01-27 23:43:54] [main] INFO  ContextHandler:781 - Started o.s.j.s.ServletContextHandler@31611954{/stages/json,null,AVAILABLE,@Spark}
[2019-01-27 23:43:54] [main] INFO  ContextHandler:781 - Started o.s.j.s.ServletContextHandler@3e598df9{/stages/stage,null,AVAILABLE,@Spark}
[2019-01-27 23:43:54] [main] INFO  ContextHandler:781 - Started o.s.j.s.ServletContextHandler@3088660d{/stages/stage/json,null,AVAILABLE,@Spark}
[2019-01-27 23:43:54] [main] INFO  ContextHandler:781 - Started o.s.j.s.ServletContextHandler@42cc13a0{/stages/pool,null,AVAILABLE,@Spark}
[2019-01-27 23:43:54] [main] INFO  ContextHandler:781 - Started o.s.j.s.ServletContextHandler@32fdec40{/stages/pool/json,null,AVAILABLE,@Spark}
[2019-01-27 23:43:54] [main] INFO  ContextHandler:781 - Started o.s.j.s.ServletContextHandler@6813a331{/storage,null,AVAILABLE,@Spark}
[2019-01-27 23:43:54] [main] INFO  ContextHandler:781 - Started o.s.j.s.ServletContextHandler@1bd81830{/storage/json,null,AVAILABLE,@Spark}
[2019-01-27 23:43:54] [main] INFO  ContextHandler:781 - Started o.s.j.s.ServletContextHandler@39ab59f8{/storage/rdd,null,AVAILABLE,@Spark}
[2019-01-27 23:43:54] [main] INFO  ContextHandler:781 - Started o.s.j.s.ServletContextHandler@64e92d61{/storage/rdd/json,null,AVAILABLE,@Spark}
[2019-01-27 23:43:54] [main] INFO  ContextHandler:781 - Started o.s.j.s.ServletContextHandler@111610e6{/environment,null,AVAILABLE,@Spark}
[2019-01-27 23:43:54] [main] INFO  ContextHandler:781 - Started o.s.j.s.ServletContextHandler@4ad4936c{/environment/json,null,AVAILABLE,@Spark}
[2019-01-27 23:43:54] [main] INFO  ContextHandler:781 - Started o.s.j.s.ServletContextHandler@29d37757{/executors,null,AVAILABLE,@Spark}
[2019-01-27 23:43:54] [main] INFO  ContextHandler:781 - Started o.s.j.s.ServletContextHandler@4fcc529{/executors/json,null,AVAILABLE,@Spark}
[2019-01-27 23:43:54] [main] INFO  ContextHandler:781 - Started o.s.j.s.ServletContextHandler@25cc7470{/executors/threadDump,null,AVAILABLE,@Spark}
[2019-01-27 23:43:54] [main] INFO  ContextHandler:781 - Started o.s.j.s.ServletContextHandler@4beddc56{/executors/threadDump/json,null,AVAILABLE,@Spark}
[2019-01-27 23:43:55] [main] INFO  ContextHandler:781 - Started o.s.j.s.ServletContextHandler@79b663b3{/static,null,AVAILABLE,@Spark}
[2019-01-27 23:43:55] [main] INFO  ContextHandler:781 - Started o.s.j.s.ServletContextHandler@26a529dc{/,null,AVAILABLE,@Spark}
[2019-01-27 23:43:55] [main] INFO  ContextHandler:781 - Started o.s.j.s.ServletContextHandler@265c5d69{/api,null,AVAILABLE,@Spark}
[2019-01-27 23:43:55] [main] INFO  ContextHandler:781 - Started o.s.j.s.ServletContextHandler@775594f2{/jobs/job/kill,null,AVAILABLE,@Spark}
[2019-01-27 23:43:55] [main] INFO  ContextHandler:781 - Started o.s.j.s.ServletContextHandler@5767b2af{/stages/stage/kill,null,AVAILABLE,@Spark}
[2019-01-27 23:43:55] [main] INFO  SparkUI:54 - Bound SparkUI to 0.0.0.0, and started at http://himrod-10:4040
[2019-01-27 23:43:55] [main] INFO  SparkContext:54 - Added JAR file:/home/zakkalyo/solr-evaluation/target/cs848-project-1.0-SNAPSHOT.jar at spark://himrod-10:44012/jars/cs848-project-1.0-SNAPSHOT.jar with timestamp 1548650635063
[2019-01-27 23:43:56] [main] INFO  RMProxy:98 - Connecting to ResourceManager at node-master/192.168.1.110:8032
[2019-01-27 23:43:56] [main] INFO  Client:54 - Requesting a new application from cluster with 9 NodeManagers
[2019-01-27 23:43:56] [main] INFO  Client:54 - Verifying our application has not requested more than the maximum memory capability of the cluster (65536 MB per container)
[2019-01-27 23:43:56] [main] INFO  Client:54 - Will allocate AM container, with 9011 MB memory including 819 MB overhead
[2019-01-27 23:43:56] [main] INFO  Client:54 - Setting up container launch context for our AM
[2019-01-27 23:43:56] [main] INFO  Client:54 - Setting up the launch environment for our AM container
[2019-01-27 23:43:57] [main] INFO  Client:54 - Preparing resources for our AM container
[2019-01-27 23:43:57] [main] WARN  Client:66 - Neither spark.yarn.jars nor spark.yarn.archive is set, falling back to uploading libraries under SPARK_HOME.
[2019-01-27 23:44:00] [main] INFO  Client:54 - Uploading resource file:/tmp/spark-6c80777c-fa5d-4cb9-bdc7-226ab73f7f9a/__spark_libs__4591257294847250213.zip -> hdfs://node-master:9000/user/zakkalyo/.sparkStaging/application_1548538970268_0036/__spark_libs__4591257294847250213.zip
[2019-01-27 23:44:02] [main] INFO  Client:54 - Uploading resource file:/tmp/spark-6c80777c-fa5d-4cb9-bdc7-226ab73f7f9a/__spark_conf__8992030596464761080.zip -> hdfs://node-master:9000/user/zakkalyo/.sparkStaging/application_1548538970268_0036/__spark_conf__.zip
[2019-01-27 23:44:02] [main] INFO  SecurityManager:54 - Changing view acls to: zakkalyo
[2019-01-27 23:44:02] [main] INFO  SecurityManager:54 - Changing modify acls to: zakkalyo
[2019-01-27 23:44:02] [main] INFO  SecurityManager:54 - Changing view acls groups to: 
[2019-01-27 23:44:02] [main] INFO  SecurityManager:54 - Changing modify acls groups to: 
[2019-01-27 23:44:02] [main] INFO  SecurityManager:54 - SecurityManager: authentication disabled; ui acls disabled; users  with view permissions: Set(zakkalyo); groups with view permissions: Set(); users  with modify permissions: Set(zakkalyo); groups with modify permissions: Set()
[2019-01-27 23:44:03] [main] INFO  Client:54 - Submitting application application_1548538970268_0036 to ResourceManager
[2019-01-27 23:44:03] [main] INFO  YarnClientImpl:273 - Submitted application application_1548538970268_0036
[2019-01-27 23:44:03] [main] INFO  SchedulerExtensionServices:54 - Starting Yarn extension services with app application_1548538970268_0036 and attemptId None
[2019-01-27 23:44:04] [main] INFO  Client:54 - Application report for application_1548538970268_0036 (state: ACCEPTED)
[2019-01-27 23:44:04] [main] INFO  Client:54 - 
	 client token: N/A
	 diagnostics: AM container is launched, waiting for AM container to Register with RM
	 ApplicationMaster host: N/A
	 ApplicationMaster RPC port: -1
	 queue: default
	 start time: 1548650643907
	 final status: UNDEFINED
	 tracking URL: http://node-master:8088/proxy/application_1548538970268_0036/
	 user: zakkalyo
[2019-01-27 23:44:05] [main] INFO  Client:54 - Application report for application_1548538970268_0036 (state: ACCEPTED)
[2019-01-27 23:44:06] [main] INFO  Client:54 - Application report for application_1548538970268_0036 (state: ACCEPTED)
[2019-01-27 23:44:07] [main] INFO  Client:54 - Application report for application_1548538970268_0036 (state: ACCEPTED)
[2019-01-27 23:44:08] [main] INFO  Client:54 - Application report for application_1548538970268_0036 (state: ACCEPTED)
[2019-01-27 23:44:09] [main] INFO  Client:54 - Application report for application_1548538970268_0036 (state: ACCEPTED)
[2019-01-27 23:44:10] [main] INFO  Client:54 - Application report for application_1548538970268_0036 (state: ACCEPTED)
[2019-01-27 23:44:11] [dispatcher-event-loop-27] INFO  YarnClientSchedulerBackend:54 - Add WebUI Filter. org.apache.hadoop.yarn.server.webproxy.amfilter.AmIpFilter, Map(PROXY_HOSTS -> node-master, PROXY_URI_BASES -> http://node-master:8088/proxy/application_1548538970268_0036), /proxy/application_1548538970268_0036
[2019-01-27 23:44:11] [dispatcher-event-loop-27] INFO  JettyUtils:54 - Adding filter org.apache.hadoop.yarn.server.webproxy.amfilter.AmIpFilter to /jobs, /jobs/json, /jobs/job, /jobs/job/json, /stages, /stages/json, /stages/stage, /stages/stage/json, /stages/pool, /stages/pool/json, /storage, /storage/json, /storage/rdd, /storage/rdd/json, /environment, /environment/json, /executors, /executors/json, /executors/threadDump, /executors/threadDump/json, /static, /, /api, /jobs/job/kill, /stages/stage/kill.
[2019-01-27 23:44:11] [main] INFO  Client:54 - Application report for application_1548538970268_0036 (state: RUNNING)
[2019-01-27 23:44:11] [main] INFO  Client:54 - 
	 client token: N/A
	 diagnostics: N/A
	 ApplicationMaster host: 192.168.1.111
	 ApplicationMaster RPC port: -1
	 queue: default
	 start time: 1548650643907
	 final status: UNDEFINED
	 tracking URL: http://node-master:8088/proxy/application_1548538970268_0036/
	 user: zakkalyo
[2019-01-27 23:44:11] [main] INFO  YarnClientSchedulerBackend:54 - Application application_1548538970268_0036 has started running.
[2019-01-27 23:44:12] [main] INFO  Utils:54 - Successfully started service 'org.apache.spark.network.netty.NettyBlockTransferService' on port 53895.
[2019-01-27 23:44:12] [main] INFO  NettyBlockTransferService:54 - Server created on himrod-10:53895
[2019-01-27 23:44:12] [main] INFO  BlockManager:54 - Using org.apache.spark.storage.RandomBlockReplicationPolicy for block replication policy
[2019-01-27 23:44:12] [main] INFO  BlockManagerMaster:54 - Registering BlockManager BlockManagerId(driver, himrod-10, 53895, None)
[2019-01-27 23:44:12] [dispatcher-event-loop-30] INFO  BlockManagerMasterEndpoint:54 - Registering block manager himrod-10:53895 with 16.9 GB RAM, BlockManagerId(driver, himrod-10, 53895, None)
[2019-01-27 23:44:12] [main] INFO  BlockManagerMaster:54 - Registered BlockManager BlockManagerId(driver, himrod-10, 53895, None)
[2019-01-27 23:44:12] [main] INFO  BlockManager:54 - Initialized BlockManager: BlockManagerId(driver, himrod-10, 53895, None)
[2019-01-27 23:44:12] [dispatcher-event-loop-31] INFO  YarnSchedulerBackend$YarnSchedulerEndpoint:54 - ApplicationMaster registered as NettyRpcEndpointRef(spark-client://YarnAM)
[2019-01-27 23:44:12] [main] INFO  JettyUtils:54 - Adding filter org.apache.hadoop.yarn.server.webproxy.amfilter.AmIpFilter to /metrics/json.
[2019-01-27 23:44:12] [main] INFO  ContextHandler:781 - Started o.s.j.s.ServletContextHandler@47058864{/metrics/json,null,AVAILABLE,@Spark}
[2019-01-27 23:44:12] [main] INFO  EventLoggingListener:54 - Logging events to hdfs://node-master:9000/spark-logs/application_1548538970268_0036
[2019-01-27 23:44:17] [dispatcher-event-loop-2] INFO  YarnSchedulerBackend$YarnDriverEndpoint:54 - Registered executor NettyRpcEndpointRef(spark-client://Executor) (192.168.1.111:58868) with ID 3
[2019-01-27 23:44:17] [dispatcher-event-loop-5] INFO  BlockManagerMasterEndpoint:54 - Registering block manager himrod-11:37383 with 25.4 GB RAM, BlockManagerId(3, himrod-11, 37383, None)
[2019-01-27 23:44:19] [dispatcher-event-loop-21] INFO  YarnSchedulerBackend$YarnDriverEndpoint:54 - Registered executor NettyRpcEndpointRef(spark-client://Executor) (192.168.1.113:46323) with ID 1
[2019-01-27 23:44:19] [dispatcher-event-loop-1] INFO  YarnSchedulerBackend$YarnDriverEndpoint:54 - Registered executor NettyRpcEndpointRef(spark-client://Executor) (192.168.1.116:39875) with ID 2
[2019-01-27 23:44:19] [dispatcher-event-loop-16] INFO  BlockManagerMasterEndpoint:54 - Registering block manager himrod-13:42497 with 25.4 GB RAM, BlockManagerId(1, himrod-13, 42497, None)
[2019-01-27 23:44:19] [dispatcher-event-loop-30] INFO  BlockManagerMasterEndpoint:54 - Registering block manager himrod-16:46976 with 25.4 GB RAM, BlockManagerId(2, himrod-16, 46976, None)
[2019-01-27 23:44:20] [dispatcher-event-loop-20] INFO  YarnSchedulerBackend$YarnDriverEndpoint:54 - Registered executor NettyRpcEndpointRef(spark-client://Executor) (192.168.1.115:34518) with ID 6
[2019-01-27 23:44:20] [dispatcher-event-loop-4] INFO  YarnSchedulerBackend$YarnDriverEndpoint:54 - Registered executor NettyRpcEndpointRef(spark-client://Executor) (192.168.1.119:50077) with ID 4
[2019-01-27 23:44:20] [dispatcher-event-loop-6] INFO  BlockManagerMasterEndpoint:54 - Registering block manager himrod-15:48429 with 25.4 GB RAM, BlockManagerId(6, himrod-15, 48429, None)
[2019-01-27 23:44:20] [dispatcher-event-loop-9] INFO  BlockManagerMasterEndpoint:54 - Registering block manager himrod-19:49108 with 25.4 GB RAM, BlockManagerId(4, himrod-19, 49108, None)
[2019-01-27 23:44:20] [dispatcher-event-loop-1] INFO  YarnSchedulerBackend$YarnDriverEndpoint:54 - Registered executor NettyRpcEndpointRef(spark-client://Executor) (192.168.1.112:47215) with ID 5
[2019-01-27 23:44:20] [dispatcher-event-loop-11] INFO  YarnSchedulerBackend$YarnDriverEndpoint:54 - Registered executor NettyRpcEndpointRef(spark-client://Executor) (192.168.1.118:51369) with ID 9
[2019-01-27 23:44:20] [dispatcher-event-loop-23] INFO  BlockManagerMasterEndpoint:54 - Registering block manager himrod-12:44598 with 25.4 GB RAM, BlockManagerId(5, himrod-12, 44598, None)
[2019-01-27 23:44:20] [dispatcher-event-loop-13] INFO  YarnSchedulerBackend$YarnDriverEndpoint:54 - Registered executor NettyRpcEndpointRef(spark-client://Executor) (192.168.1.117:53648) with ID 7
[2019-01-27 23:44:20] [dispatcher-event-loop-14] INFO  YarnSchedulerBackend$YarnDriverEndpoint:54 - Registered executor NettyRpcEndpointRef(spark-client://Executor) (192.168.1.114:36841) with ID 8
[2019-01-27 23:44:20] [main] INFO  YarnClientSchedulerBackend:54 - SchedulerBackend is ready for scheduling beginning after reached minRegisteredResourcesRatio: 0.8
[2019-01-27 23:44:20] [dispatcher-event-loop-22] INFO  BlockManagerMasterEndpoint:54 - Registering block manager himrod-18:37975 with 25.4 GB RAM, BlockManagerId(9, himrod-18, 37975, None)
[2019-01-27 23:44:21] [dispatcher-event-loop-24] INFO  BlockManagerMasterEndpoint:54 - Registering block manager himrod-14:60014 with 25.4 GB RAM, BlockManagerId(8, himrod-14, 60014, None)
[2019-01-27 23:44:21] [dispatcher-event-loop-24] INFO  BlockManagerMasterEndpoint:54 - Registering block manager himrod-17:57633 with 25.4 GB RAM, BlockManagerId(7, himrod-17, 57633, None)
[2019-01-27 23:44:21] [main] INFO  ZooKeeper:100 - Client environment:zookeeper.version=3.4.6-1569965, built on 02/20/2014 09:09 GMT
[2019-01-27 23:44:21] [main] INFO  ZooKeeper:100 - Client environment:host.name=himrod-10
[2019-01-27 23:44:21] [main] INFO  ZooKeeper:100 - Client environment:java.version=1.8.0_161
[2019-01-27 23:44:21] [main] INFO  ZooKeeper:100 - Client environment:java.vendor=Oracle Corporation
[2019-01-27 23:44:21] [main] INFO  ZooKeeper:100 - Client environment:java.home=/usr/lib/jvm/java-8-oracle/jre
[2019-01-27 23:44:21] [main] INFO  ZooKeeper:100 - Client environment:java.library.path=/localdisk5/hadoop/hadoop/lib/native:/localdisk5/hadoop/hadoop/lib/native::/usr/java/packages/lib/amd64:/usr/lib64:/lib64:/lib:/usr/lib
[2019-01-27 23:44:21] [main] INFO  ZooKeeper:100 - Client environment:java.io.tmpdir=/tmp
[2019-01-27 23:44:21] [main] INFO  ZooKeeper:100 - Client environment:java.compiler=<NA>
[2019-01-27 23:44:21] [main] INFO  ZooKeeper:100 - Client environment:os.name=Linux
[2019-01-27 23:44:21] [main] INFO  ZooKeeper:100 - Client environment:os.arch=amd64
[2019-01-27 23:44:21] [main] INFO  ZooKeeper:100 - Client environment:os.version=3.13.0-147-generic
[2019-01-27 23:44:21] [main] INFO  ZooKeeper:100 - Client environment:user.name=zakkalyo
[2019-01-27 23:44:21] [main] INFO  ZooKeeper:100 - Client environment:user.home=/home/zakkalyo
[2019-01-27 23:44:21] [main] INFO  ZooKeeper:100 - Client environment:user.dir=/home/zakkalyo/solr-evaluation
[2019-01-27 23:44:21] [main] INFO  ZooKeeper:438 - Initiating client connection, connectString=192.168.1.111:9983 sessionTimeout=30000 watcher=org.apache.solr.common.cloud.SolrZkClient$1@cec590c
[2019-01-27 23:44:21] [main-SendThread(192.168.1.111:9983)] INFO  ClientCnxn:975 - Opening socket connection to server 192.168.1.111/192.168.1.111:9983. Will not attempt to authenticate using SASL (unknown error)
[2019-01-27 23:44:21] [main-SendThread(192.168.1.111:9983)] INFO  ClientCnxn:852 - Socket connection established to 192.168.1.111/192.168.1.111:9983, initiating session
[2019-01-27 23:44:21] [main-SendThread(192.168.1.111:9983)] INFO  ClientCnxn:1235 - Session establishment complete on server 192.168.1.111/192.168.1.111:9983, sessionid = 0x103388590d30766, negotiated timeout = 30000
[2019-01-27 23:44:22] [zkConnectionManagerCallback-5-thread-1] INFO  ConnectionManager:119 - zkClient has connected
[2019-01-27 23:44:22] [main] INFO  ZkStateReader:786 - Updated live nodes from ZooKeeper... (0) -> (9)
[2019-01-27 23:44:22] [main] INFO  ZkClientClusterStateProvider:158 - Cluster at 192.168.1.111:9983 ready
[2019-01-27 23:44:23] [main] INFO  SelectSolrRDD:8 - Updated Solr query: q=raw:event&rows=1000&collection=cw09b&distrib=false&start=0&sort=id+asc&fq=_version_:[*+TO+1623338175875252224]
[2019-01-27 23:44:23] [main] INFO  SelectSolrRDD:8 - Found 1971 partitions
[2019-01-27 23:44:23] [main] INFO  SparkContext:54 - Starting job: foreachPartition at SolrRddSpark.scala:33
[2019-01-27 23:44:23] [dag-scheduler-event-loop] INFO  DAGScheduler:54 - Got job 0 (foreachPartition at SolrRddSpark.scala:33) with 1971 output partitions
[2019-01-27 23:44:23] [dag-scheduler-event-loop] INFO  DAGScheduler:54 - Final stage: ResultStage 0 (foreachPartition at SolrRddSpark.scala:33)
[2019-01-27 23:44:23] [dag-scheduler-event-loop] INFO  DAGScheduler:54 - Parents of final stage: List()
[2019-01-27 23:44:23] [dag-scheduler-event-loop] INFO  DAGScheduler:54 - Missing parents: List()
[2019-01-27 23:44:23] [dag-scheduler-event-loop] INFO  DAGScheduler:54 - Submitting ResultStage 0 (SelectSolrRDD[2] at RDD at SolrRDD.scala:26), which has no missing parents
[2019-01-27 23:44:23] [dag-scheduler-event-loop] INFO  MemoryStore:54 - Block broadcast_0 stored as values in memory (estimated size 2.3 KB, free 16.9 GB)
[2019-01-27 23:44:23] [dag-scheduler-event-loop] INFO  MemoryStore:54 - Block broadcast_0_piece0 stored as bytes in memory (estimated size 1651.0 B, free 16.9 GB)
[2019-01-27 23:44:23] [dispatcher-event-loop-4] INFO  BlockManagerInfo:54 - Added broadcast_0_piece0 in memory on himrod-10:53895 (size: 1651.0 B, free: 16.9 GB)
[2019-01-27 23:44:23] [dag-scheduler-event-loop] INFO  SparkContext:54 - Created broadcast 0 from broadcast at DAGScheduler.scala:1161
[2019-01-27 23:44:23] [dag-scheduler-event-loop] INFO  DAGScheduler:54 - Submitting 1971 missing tasks from ResultStage 0 (SelectSolrRDD[2] at RDD at SolrRDD.scala:26) (first 15 tasks are for partitions Vector(0, 1, 2, 3, 4, 5, 6, 7, 8, 9, 10, 11, 12, 13, 14))
[2019-01-27 23:44:23] [dag-scheduler-event-loop] INFO  YarnScheduler:54 - Adding task set 0.0 with 1971 tasks
[2019-01-27 23:44:23] [dispatcher-event-loop-6] INFO  TaskSetManager:54 - Starting task 0.0 in stage 0.0 (TID 0, himrod-18, executor 9, partition 0, RACK_LOCAL, 9173 bytes)
[2019-01-27 23:44:23] [dispatcher-event-loop-6] INFO  TaskSetManager:54 - Starting task 1.0 in stage 0.0 (TID 1, himrod-13, executor 1, partition 1, RACK_LOCAL, 9173 bytes)
[2019-01-27 23:44:23] [dispatcher-event-loop-6] INFO  TaskSetManager:54 - Starting task 2.0 in stage 0.0 (TID 2, himrod-16, executor 2, partition 2, RACK_LOCAL, 9173 bytes)
[2019-01-27 23:44:23] [dispatcher-event-loop-6] INFO  TaskSetManager:54 - Starting task 3.0 in stage 0.0 (TID 3, himrod-11, executor 3, partition 3, RACK_LOCAL, 9173 bytes)
[2019-01-27 23:44:23] [dispatcher-event-loop-6] INFO  TaskSetManager:54 - Starting task 4.0 in stage 0.0 (TID 4, himrod-17, executor 7, partition 4, RACK_LOCAL, 9173 bytes)
[2019-01-27 23:44:23] [dispatcher-event-loop-6] INFO  TaskSetManager:54 - Starting task 5.0 in stage 0.0 (TID 5, himrod-19, executor 4, partition 5, RACK_LOCAL, 9173 bytes)
[2019-01-27 23:44:23] [dispatcher-event-loop-6] INFO  TaskSetManager:54 - Starting task 6.0 in stage 0.0 (TID 6, himrod-12, executor 5, partition 6, RACK_LOCAL, 9173 bytes)
[2019-01-27 23:44:23] [dispatcher-event-loop-6] INFO  TaskSetManager:54 - Starting task 7.0 in stage 0.0 (TID 7, himrod-14, executor 8, partition 7, RACK_LOCAL, 9173 bytes)
[2019-01-27 23:44:23] [dispatcher-event-loop-6] INFO  TaskSetManager:54 - Starting task 8.0 in stage 0.0 (TID 8, himrod-15, executor 6, partition 8, RACK_LOCAL, 9173 bytes)
[2019-01-27 23:44:23] [dispatcher-event-loop-6] INFO  TaskSetManager:54 - Starting task 9.0 in stage 0.0 (TID 9, himrod-18, executor 9, partition 9, RACK_LOCAL, 9173 bytes)
[2019-01-27 23:44:23] [dispatcher-event-loop-6] INFO  TaskSetManager:54 - Starting task 10.0 in stage 0.0 (TID 10, himrod-13, executor 1, partition 10, RACK_LOCAL, 9174 bytes)
[2019-01-27 23:44:23] [dispatcher-event-loop-6] INFO  TaskSetManager:54 - Starting task 11.0 in stage 0.0 (TID 11, himrod-16, executor 2, partition 11, RACK_LOCAL, 9174 bytes)
[2019-01-27 23:44:23] [dispatcher-event-loop-6] INFO  TaskSetManager:54 - Starting task 12.0 in stage 0.0 (TID 12, himrod-11, executor 3, partition 12, RACK_LOCAL, 9174 bytes)
[2019-01-27 23:44:23] [dispatcher-event-loop-6] INFO  TaskSetManager:54 - Starting task 13.0 in stage 0.0 (TID 13, himrod-17, executor 7, partition 13, RACK_LOCAL, 9174 bytes)
[2019-01-27 23:44:23] [dispatcher-event-loop-6] INFO  TaskSetManager:54 - Starting task 14.0 in stage 0.0 (TID 14, himrod-19, executor 4, partition 14, RACK_LOCAL, 9174 bytes)
[2019-01-27 23:44:23] [dispatcher-event-loop-6] INFO  TaskSetManager:54 - Starting task 15.0 in stage 0.0 (TID 15, himrod-12, executor 5, partition 15, RACK_LOCAL, 9174 bytes)
[2019-01-27 23:44:23] [dispatcher-event-loop-6] INFO  TaskSetManager:54 - Starting task 16.0 in stage 0.0 (TID 16, himrod-14, executor 8, partition 16, RACK_LOCAL, 9174 bytes)
[2019-01-27 23:44:23] [dispatcher-event-loop-6] INFO  TaskSetManager:54 - Starting task 17.0 in stage 0.0 (TID 17, himrod-15, executor 6, partition 17, RACK_LOCAL, 9174 bytes)
[2019-01-27 23:44:23] [dispatcher-event-loop-6] INFO  TaskSetManager:54 - Starting task 18.0 in stage 0.0 (TID 18, himrod-18, executor 9, partition 18, RACK_LOCAL, 9174 bytes)
[2019-01-27 23:44:23] [dispatcher-event-loop-6] INFO  TaskSetManager:54 - Starting task 19.0 in stage 0.0 (TID 19, himrod-13, executor 1, partition 19, RACK_LOCAL, 9174 bytes)
[2019-01-27 23:44:23] [dispatcher-event-loop-6] INFO  TaskSetManager:54 - Starting task 20.0 in stage 0.0 (TID 20, himrod-16, executor 2, partition 20, RACK_LOCAL, 9174 bytes)
[2019-01-27 23:44:23] [dispatcher-event-loop-6] INFO  TaskSetManager:54 - Starting task 21.0 in stage 0.0 (TID 21, himrod-11, executor 3, partition 21, RACK_LOCAL, 9174 bytes)
[2019-01-27 23:44:23] [dispatcher-event-loop-6] INFO  TaskSetManager:54 - Starting task 22.0 in stage 0.0 (TID 22, himrod-17, executor 7, partition 22, RACK_LOCAL, 9174 bytes)
[2019-01-27 23:44:23] [dispatcher-event-loop-6] INFO  TaskSetManager:54 - Starting task 23.0 in stage 0.0 (TID 23, himrod-19, executor 4, partition 23, RACK_LOCAL, 9174 bytes)
[2019-01-27 23:44:23] [dispatcher-event-loop-6] INFO  TaskSetManager:54 - Starting task 24.0 in stage 0.0 (TID 24, himrod-12, executor 5, partition 24, RACK_LOCAL, 9174 bytes)
[2019-01-27 23:44:23] [dispatcher-event-loop-6] INFO  TaskSetManager:54 - Starting task 25.0 in stage 0.0 (TID 25, himrod-14, executor 8, partition 25, RACK_LOCAL, 9174 bytes)
[2019-01-27 23:44:23] [dispatcher-event-loop-6] INFO  TaskSetManager:54 - Starting task 26.0 in stage 0.0 (TID 26, himrod-15, executor 6, partition 26, RACK_LOCAL, 9174 bytes)
[2019-01-27 23:44:23] [dispatcher-event-loop-6] INFO  TaskSetManager:54 - Starting task 27.0 in stage 0.0 (TID 27, himrod-18, executor 9, partition 27, RACK_LOCAL, 9174 bytes)
[2019-01-27 23:44:23] [dispatcher-event-loop-6] INFO  TaskSetManager:54 - Starting task 28.0 in stage 0.0 (TID 28, himrod-13, executor 1, partition 28, RACK_LOCAL, 9174 bytes)
[2019-01-27 23:44:23] [dispatcher-event-loop-6] INFO  TaskSetManager:54 - Starting task 29.0 in stage 0.0 (TID 29, himrod-16, executor 2, partition 29, RACK_LOCAL, 9174 bytes)
[2019-01-27 23:44:23] [dispatcher-event-loop-6] INFO  TaskSetManager:54 - Starting task 30.0 in stage 0.0 (TID 30, himrod-11, executor 3, partition 30, RACK_LOCAL, 9174 bytes)
[2019-01-27 23:44:23] [dispatcher-event-loop-6] INFO  TaskSetManager:54 - Starting task 31.0 in stage 0.0 (TID 31, himrod-17, executor 7, partition 31, RACK_LOCAL, 9174 bytes)
[2019-01-27 23:44:23] [dispatcher-event-loop-6] INFO  TaskSetManager:54 - Starting task 32.0 in stage 0.0 (TID 32, himrod-19, executor 4, partition 32, RACK_LOCAL, 9174 bytes)
[2019-01-27 23:44:23] [dispatcher-event-loop-6] INFO  TaskSetManager:54 - Starting task 33.0 in stage 0.0 (TID 33, himrod-12, executor 5, partition 33, RACK_LOCAL, 9174 bytes)
[2019-01-27 23:44:23] [dispatcher-event-loop-6] INFO  TaskSetManager:54 - Starting task 34.0 in stage 0.0 (TID 34, himrod-14, executor 8, partition 34, RACK_LOCAL, 9174 bytes)
[2019-01-27 23:44:23] [dispatcher-event-loop-6] INFO  TaskSetManager:54 - Starting task 35.0 in stage 0.0 (TID 35, himrod-15, executor 6, partition 35, RACK_LOCAL, 9174 bytes)
[2019-01-27 23:44:23] [dispatcher-event-loop-6] INFO  TaskSetManager:54 - Starting task 36.0 in stage 0.0 (TID 36, himrod-18, executor 9, partition 36, RACK_LOCAL, 9174 bytes)
[2019-01-27 23:44:23] [dispatcher-event-loop-6] INFO  TaskSetManager:54 - Starting task 37.0 in stage 0.0 (TID 37, himrod-13, executor 1, partition 37, RACK_LOCAL, 9174 bytes)
[2019-01-27 23:44:23] [dispatcher-event-loop-6] INFO  TaskSetManager:54 - Starting task 38.0 in stage 0.0 (TID 38, himrod-16, executor 2, partition 38, RACK_LOCAL, 9174 bytes)
[2019-01-27 23:44:23] [dispatcher-event-loop-6] INFO  TaskSetManager:54 - Starting task 39.0 in stage 0.0 (TID 39, himrod-11, executor 3, partition 39, RACK_LOCAL, 9174 bytes)
[2019-01-27 23:44:23] [dispatcher-event-loop-6] INFO  TaskSetManager:54 - Starting task 40.0 in stage 0.0 (TID 40, himrod-17, executor 7, partition 40, RACK_LOCAL, 9174 bytes)
[2019-01-27 23:44:23] [dispatcher-event-loop-6] INFO  TaskSetManager:54 - Starting task 41.0 in stage 0.0 (TID 41, himrod-19, executor 4, partition 41, RACK_LOCAL, 9174 bytes)
[2019-01-27 23:44:23] [dispatcher-event-loop-6] INFO  TaskSetManager:54 - Starting task 42.0 in stage 0.0 (TID 42, himrod-12, executor 5, partition 42, RACK_LOCAL, 9174 bytes)
[2019-01-27 23:44:23] [dispatcher-event-loop-6] INFO  TaskSetManager:54 - Starting task 43.0 in stage 0.0 (TID 43, himrod-14, executor 8, partition 43, RACK_LOCAL, 9174 bytes)
[2019-01-27 23:44:23] [dispatcher-event-loop-6] INFO  TaskSetManager:54 - Starting task 44.0 in stage 0.0 (TID 44, himrod-15, executor 6, partition 44, RACK_LOCAL, 9174 bytes)
[2019-01-27 23:44:23] [dispatcher-event-loop-6] INFO  TaskSetManager:54 - Starting task 45.0 in stage 0.0 (TID 45, himrod-18, executor 9, partition 45, RACK_LOCAL, 9174 bytes)
[2019-01-27 23:44:23] [dispatcher-event-loop-6] INFO  TaskSetManager:54 - Starting task 46.0 in stage 0.0 (TID 46, himrod-13, executor 1, partition 46, RACK_LOCAL, 9174 bytes)
[2019-01-27 23:44:23] [dispatcher-event-loop-6] INFO  TaskSetManager:54 - Starting task 47.0 in stage 0.0 (TID 47, himrod-16, executor 2, partition 47, RACK_LOCAL, 9174 bytes)
[2019-01-27 23:44:23] [dispatcher-event-loop-6] INFO  TaskSetManager:54 - Starting task 48.0 in stage 0.0 (TID 48, himrod-11, executor 3, partition 48, RACK_LOCAL, 9174 bytes)
[2019-01-27 23:44:23] [dispatcher-event-loop-6] INFO  TaskSetManager:54 - Starting task 49.0 in stage 0.0 (TID 49, himrod-17, executor 7, partition 49, RACK_LOCAL, 9174 bytes)
[2019-01-27 23:44:23] [dispatcher-event-loop-6] INFO  TaskSetManager:54 - Starting task 50.0 in stage 0.0 (TID 50, himrod-19, executor 4, partition 50, RACK_LOCAL, 9174 bytes)
[2019-01-27 23:44:23] [dispatcher-event-loop-6] INFO  TaskSetManager:54 - Starting task 51.0 in stage 0.0 (TID 51, himrod-12, executor 5, partition 51, RACK_LOCAL, 9174 bytes)
[2019-01-27 23:44:23] [dispatcher-event-loop-6] INFO  TaskSetManager:54 - Starting task 52.0 in stage 0.0 (TID 52, himrod-14, executor 8, partition 52, RACK_LOCAL, 9174 bytes)
[2019-01-27 23:44:23] [dispatcher-event-loop-6] INFO  TaskSetManager:54 - Starting task 53.0 in stage 0.0 (TID 53, himrod-15, executor 6, partition 53, RACK_LOCAL, 9174 bytes)
[2019-01-27 23:44:23] [dispatcher-event-loop-6] INFO  TaskSetManager:54 - Starting task 54.0 in stage 0.0 (TID 54, himrod-18, executor 9, partition 54, RACK_LOCAL, 9174 bytes)
[2019-01-27 23:44:23] [dispatcher-event-loop-6] INFO  TaskSetManager:54 - Starting task 55.0 in stage 0.0 (TID 55, himrod-13, executor 1, partition 55, RACK_LOCAL, 9174 bytes)
[2019-01-27 23:44:23] [dispatcher-event-loop-6] INFO  TaskSetManager:54 - Starting task 56.0 in stage 0.0 (TID 56, himrod-16, executor 2, partition 56, RACK_LOCAL, 9174 bytes)
[2019-01-27 23:44:23] [dispatcher-event-loop-6] INFO  TaskSetManager:54 - Starting task 57.0 in stage 0.0 (TID 57, himrod-11, executor 3, partition 57, RACK_LOCAL, 9174 bytes)
[2019-01-27 23:44:23] [dispatcher-event-loop-6] INFO  TaskSetManager:54 - Starting task 58.0 in stage 0.0 (TID 58, himrod-17, executor 7, partition 58, RACK_LOCAL, 9174 bytes)
[2019-01-27 23:44:23] [dispatcher-event-loop-6] INFO  TaskSetManager:54 - Starting task 59.0 in stage 0.0 (TID 59, himrod-19, executor 4, partition 59, RACK_LOCAL, 9174 bytes)
[2019-01-27 23:44:23] [dispatcher-event-loop-6] INFO  TaskSetManager:54 - Starting task 60.0 in stage 0.0 (TID 60, himrod-12, executor 5, partition 60, RACK_LOCAL, 9174 bytes)
[2019-01-27 23:44:23] [dispatcher-event-loop-6] INFO  TaskSetManager:54 - Starting task 61.0 in stage 0.0 (TID 61, himrod-14, executor 8, partition 61, RACK_LOCAL, 9174 bytes)
[2019-01-27 23:44:23] [dispatcher-event-loop-6] INFO  TaskSetManager:54 - Starting task 62.0 in stage 0.0 (TID 62, himrod-15, executor 6, partition 62, RACK_LOCAL, 9174 bytes)
[2019-01-27 23:44:23] [dispatcher-event-loop-6] INFO  TaskSetManager:54 - Starting task 63.0 in stage 0.0 (TID 63, himrod-18, executor 9, partition 63, RACK_LOCAL, 9174 bytes)
[2019-01-27 23:44:23] [dispatcher-event-loop-6] INFO  TaskSetManager:54 - Starting task 64.0 in stage 0.0 (TID 64, himrod-13, executor 1, partition 64, RACK_LOCAL, 9174 bytes)
[2019-01-27 23:44:23] [dispatcher-event-loop-6] INFO  TaskSetManager:54 - Starting task 65.0 in stage 0.0 (TID 65, himrod-16, executor 2, partition 65, RACK_LOCAL, 9174 bytes)
[2019-01-27 23:44:23] [dispatcher-event-loop-6] INFO  TaskSetManager:54 - Starting task 66.0 in stage 0.0 (TID 66, himrod-11, executor 3, partition 66, RACK_LOCAL, 9174 bytes)
[2019-01-27 23:44:23] [dispatcher-event-loop-6] INFO  TaskSetManager:54 - Starting task 67.0 in stage 0.0 (TID 67, himrod-17, executor 7, partition 67, RACK_LOCAL, 9174 bytes)
[2019-01-27 23:44:23] [dispatcher-event-loop-6] INFO  TaskSetManager:54 - Starting task 68.0 in stage 0.0 (TID 68, himrod-19, executor 4, partition 68, RACK_LOCAL, 9174 bytes)
[2019-01-27 23:44:23] [dispatcher-event-loop-6] INFO  TaskSetManager:54 - Starting task 69.0 in stage 0.0 (TID 69, himrod-12, executor 5, partition 69, RACK_LOCAL, 9174 bytes)
[2019-01-27 23:44:23] [dispatcher-event-loop-6] INFO  TaskSetManager:54 - Starting task 70.0 in stage 0.0 (TID 70, himrod-14, executor 8, partition 70, RACK_LOCAL, 9174 bytes)
[2019-01-27 23:44:23] [dispatcher-event-loop-6] INFO  TaskSetManager:54 - Starting task 71.0 in stage 0.0 (TID 71, himrod-15, executor 6, partition 71, RACK_LOCAL, 9174 bytes)
[2019-01-27 23:44:23] [dispatcher-event-loop-6] INFO  TaskSetManager:54 - Starting task 72.0 in stage 0.0 (TID 72, himrod-18, executor 9, partition 72, RACK_LOCAL, 9174 bytes)
[2019-01-27 23:44:23] [dispatcher-event-loop-6] INFO  TaskSetManager:54 - Starting task 73.0 in stage 0.0 (TID 73, himrod-13, executor 1, partition 73, RACK_LOCAL, 9174 bytes)
[2019-01-27 23:44:23] [dispatcher-event-loop-6] INFO  TaskSetManager:54 - Starting task 74.0 in stage 0.0 (TID 74, himrod-16, executor 2, partition 74, RACK_LOCAL, 9174 bytes)
[2019-01-27 23:44:23] [dispatcher-event-loop-6] INFO  TaskSetManager:54 - Starting task 75.0 in stage 0.0 (TID 75, himrod-11, executor 3, partition 75, RACK_LOCAL, 9174 bytes)
[2019-01-27 23:44:23] [dispatcher-event-loop-6] INFO  TaskSetManager:54 - Starting task 76.0 in stage 0.0 (TID 76, himrod-17, executor 7, partition 76, RACK_LOCAL, 9174 bytes)
[2019-01-27 23:44:23] [dispatcher-event-loop-6] INFO  TaskSetManager:54 - Starting task 77.0 in stage 0.0 (TID 77, himrod-19, executor 4, partition 77, RACK_LOCAL, 9174 bytes)
[2019-01-27 23:44:23] [dispatcher-event-loop-6] INFO  TaskSetManager:54 - Starting task 78.0 in stage 0.0 (TID 78, himrod-12, executor 5, partition 78, RACK_LOCAL, 9174 bytes)
[2019-01-27 23:44:23] [dispatcher-event-loop-6] INFO  TaskSetManager:54 - Starting task 79.0 in stage 0.0 (TID 79, himrod-14, executor 8, partition 79, RACK_LOCAL, 9174 bytes)
[2019-01-27 23:44:23] [dispatcher-event-loop-6] INFO  TaskSetManager:54 - Starting task 80.0 in stage 0.0 (TID 80, himrod-15, executor 6, partition 80, RACK_LOCAL, 9174 bytes)
[2019-01-27 23:44:23] [dispatcher-event-loop-6] INFO  TaskSetManager:54 - Starting task 81.0 in stage 0.0 (TID 81, himrod-18, executor 9, partition 81, RACK_LOCAL, 9174 bytes)
[2019-01-27 23:44:23] [dispatcher-event-loop-6] INFO  TaskSetManager:54 - Starting task 82.0 in stage 0.0 (TID 82, himrod-13, executor 1, partition 82, RACK_LOCAL, 9174 bytes)
[2019-01-27 23:44:23] [dispatcher-event-loop-6] INFO  TaskSetManager:54 - Starting task 83.0 in stage 0.0 (TID 83, himrod-16, executor 2, partition 83, RACK_LOCAL, 9174 bytes)
[2019-01-27 23:44:23] [dispatcher-event-loop-6] INFO  TaskSetManager:54 - Starting task 84.0 in stage 0.0 (TID 84, himrod-11, executor 3, partition 84, RACK_LOCAL, 9174 bytes)
[2019-01-27 23:44:23] [dispatcher-event-loop-6] INFO  TaskSetManager:54 - Starting task 85.0 in stage 0.0 (TID 85, himrod-17, executor 7, partition 85, RACK_LOCAL, 9174 bytes)
[2019-01-27 23:44:23] [dispatcher-event-loop-6] INFO  TaskSetManager:54 - Starting task 86.0 in stage 0.0 (TID 86, himrod-19, executor 4, partition 86, RACK_LOCAL, 9174 bytes)
[2019-01-27 23:44:23] [dispatcher-event-loop-6] INFO  TaskSetManager:54 - Starting task 87.0 in stage 0.0 (TID 87, himrod-12, executor 5, partition 87, RACK_LOCAL, 9174 bytes)
[2019-01-27 23:44:23] [dispatcher-event-loop-6] INFO  TaskSetManager:54 - Starting task 88.0 in stage 0.0 (TID 88, himrod-14, executor 8, partition 88, RACK_LOCAL, 9174 bytes)
[2019-01-27 23:44:23] [dispatcher-event-loop-6] INFO  TaskSetManager:54 - Starting task 89.0 in stage 0.0 (TID 89, himrod-15, executor 6, partition 89, RACK_LOCAL, 9174 bytes)
[2019-01-27 23:44:23] [dispatcher-event-loop-6] INFO  TaskSetManager:54 - Starting task 90.0 in stage 0.0 (TID 90, himrod-18, executor 9, partition 90, RACK_LOCAL, 9174 bytes)
[2019-01-27 23:44:23] [dispatcher-event-loop-6] INFO  TaskSetManager:54 - Starting task 91.0 in stage 0.0 (TID 91, himrod-13, executor 1, partition 91, RACK_LOCAL, 9174 bytes)
[2019-01-27 23:44:23] [dispatcher-event-loop-6] INFO  TaskSetManager:54 - Starting task 92.0 in stage 0.0 (TID 92, himrod-16, executor 2, partition 92, RACK_LOCAL, 9174 bytes)
[2019-01-27 23:44:23] [dispatcher-event-loop-6] INFO  TaskSetManager:54 - Starting task 93.0 in stage 0.0 (TID 93, himrod-11, executor 3, partition 93, RACK_LOCAL, 9174 bytes)
[2019-01-27 23:44:23] [dispatcher-event-loop-6] INFO  TaskSetManager:54 - Starting task 94.0 in stage 0.0 (TID 94, himrod-17, executor 7, partition 94, RACK_LOCAL, 9174 bytes)
[2019-01-27 23:44:23] [dispatcher-event-loop-6] INFO  TaskSetManager:54 - Starting task 95.0 in stage 0.0 (TID 95, himrod-19, executor 4, partition 95, RACK_LOCAL, 9174 bytes)
[2019-01-27 23:44:23] [dispatcher-event-loop-6] INFO  TaskSetManager:54 - Starting task 96.0 in stage 0.0 (TID 96, himrod-12, executor 5, partition 96, RACK_LOCAL, 9174 bytes)
[2019-01-27 23:44:23] [dispatcher-event-loop-6] INFO  TaskSetManager:54 - Starting task 97.0 in stage 0.0 (TID 97, himrod-14, executor 8, partition 97, RACK_LOCAL, 9174 bytes)
[2019-01-27 23:44:23] [dispatcher-event-loop-6] INFO  TaskSetManager:54 - Starting task 98.0 in stage 0.0 (TID 98, himrod-15, executor 6, partition 98, RACK_LOCAL, 9174 bytes)
[2019-01-27 23:44:23] [dispatcher-event-loop-6] INFO  TaskSetManager:54 - Starting task 99.0 in stage 0.0 (TID 99, himrod-18, executor 9, partition 99, RACK_LOCAL, 9174 bytes)
[2019-01-27 23:44:23] [dispatcher-event-loop-6] INFO  TaskSetManager:54 - Starting task 100.0 in stage 0.0 (TID 100, himrod-13, executor 1, partition 100, RACK_LOCAL, 9175 bytes)
[2019-01-27 23:44:23] [dispatcher-event-loop-6] INFO  TaskSetManager:54 - Starting task 101.0 in stage 0.0 (TID 101, himrod-16, executor 2, partition 101, RACK_LOCAL, 9175 bytes)
[2019-01-27 23:44:23] [dispatcher-event-loop-6] INFO  TaskSetManager:54 - Starting task 102.0 in stage 0.0 (TID 102, himrod-11, executor 3, partition 102, RACK_LOCAL, 9175 bytes)
[2019-01-27 23:44:23] [dispatcher-event-loop-6] INFO  TaskSetManager:54 - Starting task 103.0 in stage 0.0 (TID 103, himrod-17, executor 7, partition 103, RACK_LOCAL, 9175 bytes)
[2019-01-27 23:44:23] [dispatcher-event-loop-6] INFO  TaskSetManager:54 - Starting task 104.0 in stage 0.0 (TID 104, himrod-19, executor 4, partition 104, RACK_LOCAL, 9175 bytes)
[2019-01-27 23:44:23] [dispatcher-event-loop-6] INFO  TaskSetManager:54 - Starting task 105.0 in stage 0.0 (TID 105, himrod-12, executor 5, partition 105, RACK_LOCAL, 9175 bytes)
[2019-01-27 23:44:23] [dispatcher-event-loop-6] INFO  TaskSetManager:54 - Starting task 106.0 in stage 0.0 (TID 106, himrod-14, executor 8, partition 106, RACK_LOCAL, 9175 bytes)
[2019-01-27 23:44:23] [dispatcher-event-loop-6] INFO  TaskSetManager:54 - Starting task 107.0 in stage 0.0 (TID 107, himrod-15, executor 6, partition 107, RACK_LOCAL, 9175 bytes)
[2019-01-27 23:44:23] [dispatcher-event-loop-6] INFO  TaskSetManager:54 - Starting task 108.0 in stage 0.0 (TID 108, himrod-18, executor 9, partition 108, RACK_LOCAL, 9175 bytes)
[2019-01-27 23:44:23] [dispatcher-event-loop-6] INFO  TaskSetManager:54 - Starting task 109.0 in stage 0.0 (TID 109, himrod-13, executor 1, partition 109, RACK_LOCAL, 9175 bytes)
[2019-01-27 23:44:23] [dispatcher-event-loop-6] INFO  TaskSetManager:54 - Starting task 110.0 in stage 0.0 (TID 110, himrod-16, executor 2, partition 110, RACK_LOCAL, 9175 bytes)
[2019-01-27 23:44:23] [dispatcher-event-loop-6] INFO  TaskSetManager:54 - Starting task 111.0 in stage 0.0 (TID 111, himrod-11, executor 3, partition 111, RACK_LOCAL, 9175 bytes)
[2019-01-27 23:44:23] [dispatcher-event-loop-6] INFO  TaskSetManager:54 - Starting task 112.0 in stage 0.0 (TID 112, himrod-17, executor 7, partition 112, RACK_LOCAL, 9175 bytes)
[2019-01-27 23:44:23] [dispatcher-event-loop-6] INFO  TaskSetManager:54 - Starting task 113.0 in stage 0.0 (TID 113, himrod-19, executor 4, partition 113, RACK_LOCAL, 9175 bytes)
[2019-01-27 23:44:23] [dispatcher-event-loop-6] INFO  TaskSetManager:54 - Starting task 114.0 in stage 0.0 (TID 114, himrod-12, executor 5, partition 114, RACK_LOCAL, 9175 bytes)
[2019-01-27 23:44:23] [dispatcher-event-loop-6] INFO  TaskSetManager:54 - Starting task 115.0 in stage 0.0 (TID 115, himrod-14, executor 8, partition 115, RACK_LOCAL, 9175 bytes)
[2019-01-27 23:44:23] [dispatcher-event-loop-6] INFO  TaskSetManager:54 - Starting task 116.0 in stage 0.0 (TID 116, himrod-15, executor 6, partition 116, RACK_LOCAL, 9175 bytes)
[2019-01-27 23:44:23] [dispatcher-event-loop-6] INFO  TaskSetManager:54 - Starting task 117.0 in stage 0.0 (TID 117, himrod-18, executor 9, partition 117, RACK_LOCAL, 9175 bytes)
[2019-01-27 23:44:23] [dispatcher-event-loop-6] INFO  TaskSetManager:54 - Starting task 118.0 in stage 0.0 (TID 118, himrod-13, executor 1, partition 118, RACK_LOCAL, 9175 bytes)
[2019-01-27 23:44:23] [dispatcher-event-loop-6] INFO  TaskSetManager:54 - Starting task 119.0 in stage 0.0 (TID 119, himrod-16, executor 2, partition 119, RACK_LOCAL, 9175 bytes)
[2019-01-27 23:44:23] [dispatcher-event-loop-6] INFO  TaskSetManager:54 - Starting task 120.0 in stage 0.0 (TID 120, himrod-11, executor 3, partition 120, RACK_LOCAL, 9175 bytes)
[2019-01-27 23:44:23] [dispatcher-event-loop-6] INFO  TaskSetManager:54 - Starting task 121.0 in stage 0.0 (TID 121, himrod-17, executor 7, partition 121, RACK_LOCAL, 9175 bytes)
[2019-01-27 23:44:23] [dispatcher-event-loop-6] INFO  TaskSetManager:54 - Starting task 122.0 in stage 0.0 (TID 122, himrod-19, executor 4, partition 122, RACK_LOCAL, 9175 bytes)
[2019-01-27 23:44:23] [dispatcher-event-loop-6] INFO  TaskSetManager:54 - Starting task 123.0 in stage 0.0 (TID 123, himrod-12, executor 5, partition 123, RACK_LOCAL, 9175 bytes)
[2019-01-27 23:44:23] [dispatcher-event-loop-6] INFO  TaskSetManager:54 - Starting task 124.0 in stage 0.0 (TID 124, himrod-14, executor 8, partition 124, RACK_LOCAL, 9175 bytes)
[2019-01-27 23:44:23] [dispatcher-event-loop-6] INFO  TaskSetManager:54 - Starting task 125.0 in stage 0.0 (TID 125, himrod-15, executor 6, partition 125, RACK_LOCAL, 9175 bytes)
[2019-01-27 23:44:23] [dispatcher-event-loop-6] INFO  TaskSetManager:54 - Starting task 126.0 in stage 0.0 (TID 126, himrod-18, executor 9, partition 126, RACK_LOCAL, 9175 bytes)
[2019-01-27 23:44:23] [dispatcher-event-loop-6] INFO  TaskSetManager:54 - Starting task 127.0 in stage 0.0 (TID 127, himrod-13, executor 1, partition 127, RACK_LOCAL, 9175 bytes)
[2019-01-27 23:44:23] [dispatcher-event-loop-6] INFO  TaskSetManager:54 - Starting task 128.0 in stage 0.0 (TID 128, himrod-16, executor 2, partition 128, RACK_LOCAL, 9175 bytes)
[2019-01-27 23:44:23] [dispatcher-event-loop-6] INFO  TaskSetManager:54 - Starting task 129.0 in stage 0.0 (TID 129, himrod-11, executor 3, partition 129, RACK_LOCAL, 9175 bytes)
[2019-01-27 23:44:23] [dispatcher-event-loop-6] INFO  TaskSetManager:54 - Starting task 130.0 in stage 0.0 (TID 130, himrod-17, executor 7, partition 130, RACK_LOCAL, 9175 bytes)
[2019-01-27 23:44:23] [dispatcher-event-loop-6] INFO  TaskSetManager:54 - Starting task 131.0 in stage 0.0 (TID 131, himrod-19, executor 4, partition 131, RACK_LOCAL, 9175 bytes)
[2019-01-27 23:44:23] [dispatcher-event-loop-6] INFO  TaskSetManager:54 - Starting task 132.0 in stage 0.0 (TID 132, himrod-12, executor 5, partition 132, RACK_LOCAL, 9175 bytes)
[2019-01-27 23:44:23] [dispatcher-event-loop-6] INFO  TaskSetManager:54 - Starting task 133.0 in stage 0.0 (TID 133, himrod-14, executor 8, partition 133, RACK_LOCAL, 9175 bytes)
[2019-01-27 23:44:23] [dispatcher-event-loop-6] INFO  TaskSetManager:54 - Starting task 134.0 in stage 0.0 (TID 134, himrod-15, executor 6, partition 134, RACK_LOCAL, 9175 bytes)
[2019-01-27 23:44:23] [dispatcher-event-loop-6] INFO  TaskSetManager:54 - Starting task 135.0 in stage 0.0 (TID 135, himrod-18, executor 9, partition 135, RACK_LOCAL, 9175 bytes)
[2019-01-27 23:44:23] [dispatcher-event-loop-6] INFO  TaskSetManager:54 - Starting task 136.0 in stage 0.0 (TID 136, himrod-13, executor 1, partition 136, RACK_LOCAL, 9175 bytes)
[2019-01-27 23:44:23] [dispatcher-event-loop-6] INFO  TaskSetManager:54 - Starting task 137.0 in stage 0.0 (TID 137, himrod-16, executor 2, partition 137, RACK_LOCAL, 9175 bytes)
[2019-01-27 23:44:23] [dispatcher-event-loop-6] INFO  TaskSetManager:54 - Starting task 138.0 in stage 0.0 (TID 138, himrod-11, executor 3, partition 138, RACK_LOCAL, 9175 bytes)
[2019-01-27 23:44:23] [dispatcher-event-loop-6] INFO  TaskSetManager:54 - Starting task 139.0 in stage 0.0 (TID 139, himrod-17, executor 7, partition 139, RACK_LOCAL, 9175 bytes)
[2019-01-27 23:44:23] [dispatcher-event-loop-6] INFO  TaskSetManager:54 - Starting task 140.0 in stage 0.0 (TID 140, himrod-19, executor 4, partition 140, RACK_LOCAL, 9175 bytes)
[2019-01-27 23:44:23] [dispatcher-event-loop-6] INFO  TaskSetManager:54 - Starting task 141.0 in stage 0.0 (TID 141, himrod-12, executor 5, partition 141, RACK_LOCAL, 9175 bytes)
[2019-01-27 23:44:23] [dispatcher-event-loop-6] INFO  TaskSetManager:54 - Starting task 142.0 in stage 0.0 (TID 142, himrod-14, executor 8, partition 142, RACK_LOCAL, 9175 bytes)
[2019-01-27 23:44:23] [dispatcher-event-loop-6] INFO  TaskSetManager:54 - Starting task 143.0 in stage 0.0 (TID 143, himrod-15, executor 6, partition 143, RACK_LOCAL, 9175 bytes)
[2019-01-27 23:44:29] [dispatcher-event-loop-6] INFO  BlockManagerInfo:54 - Added broadcast_0_piece0 in memory on himrod-15:48429 (size: 1651.0 B, free: 25.4 GB)
[2019-01-27 23:44:30] [dispatcher-event-loop-21] INFO  BlockManagerInfo:54 - Added broadcast_0_piece0 in memory on himrod-12:44598 (size: 1651.0 B, free: 25.4 GB)
[2019-01-27 23:44:30] [dispatcher-event-loop-9] INFO  BlockManagerInfo:54 - Added broadcast_0_piece0 in memory on himrod-19:49108 (size: 1651.0 B, free: 25.4 GB)
[2019-01-27 23:44:30] [dispatcher-event-loop-26] INFO  BlockManagerInfo:54 - Added broadcast_0_piece0 in memory on himrod-11:37383 (size: 1651.0 B, free: 25.4 GB)
[2019-01-27 23:44:31] [dispatcher-event-loop-12] INFO  BlockManagerInfo:54 - Added broadcast_0_piece0 in memory on himrod-18:37975 (size: 1651.0 B, free: 25.4 GB)
[2019-01-27 23:44:31] [dispatcher-event-loop-11] INFO  BlockManagerInfo:54 - Added broadcast_0_piece0 in memory on himrod-16:46976 (size: 1651.0 B, free: 25.4 GB)
[2019-01-27 23:44:31] [dispatcher-event-loop-25] INFO  BlockManagerInfo:54 - Added broadcast_0_piece0 in memory on himrod-17:57633 (size: 1651.0 B, free: 25.4 GB)
[2019-01-27 23:44:31] [dispatcher-event-loop-2] INFO  BlockManagerInfo:54 - Added broadcast_0_piece0 in memory on himrod-13:42497 (size: 1651.0 B, free: 25.4 GB)
[2019-01-27 23:44:32] [dispatcher-event-loop-17] INFO  BlockManagerInfo:54 - Added broadcast_0_piece0 in memory on himrod-14:60014 (size: 1651.0 B, free: 25.4 GB)
[2019-01-27 23:45:25] [dispatcher-event-loop-31] INFO  TaskSetManager:54 - Starting task 144.0 in stage 0.0 (TID 144, himrod-12, executor 5, partition 144, RACK_LOCAL, 9175 bytes)
[2019-01-27 23:45:25] [task-result-getter-0] INFO  TaskSetManager:54 - Finished task 132.0 in stage 0.0 (TID 132) in 61509 ms on himrod-12 (executor 5) (1/1971)
[2019-01-27 23:45:25] [dispatcher-event-loop-5] INFO  TaskSetManager:54 - Starting task 145.0 in stage 0.0 (TID 145, himrod-11, executor 3, partition 145, RACK_LOCAL, 9175 bytes)
[2019-01-27 23:45:25] [task-result-getter-1] INFO  TaskSetManager:54 - Finished task 57.0 in stage 0.0 (TID 57) in 62054 ms on himrod-11 (executor 3) (2/1971)
[2019-01-27 23:45:25] [dispatcher-event-loop-18] INFO  TaskSetManager:54 - Starting task 146.0 in stage 0.0 (TID 146, himrod-12, executor 5, partition 146, RACK_LOCAL, 9175 bytes)
[2019-01-27 23:45:25] [task-result-getter-2] INFO  TaskSetManager:54 - Finished task 105.0 in stage 0.0 (TID 105) in 62140 ms on himrod-12 (executor 5) (3/1971)
[2019-01-27 23:45:26] [dispatcher-event-loop-15] INFO  TaskSetManager:54 - Starting task 147.0 in stage 0.0 (TID 147, himrod-11, executor 3, partition 147, RACK_LOCAL, 9175 bytes)
[2019-01-27 23:45:26] [task-result-getter-3] INFO  TaskSetManager:54 - Finished task 102.0 in stage 0.0 (TID 102) in 62211 ms on himrod-11 (executor 3) (4/1971)
[2019-01-27 23:45:26] [dispatcher-event-loop-17] INFO  TaskSetManager:54 - Starting task 148.0 in stage 0.0 (TID 148, himrod-12, executor 5, partition 148, RACK_LOCAL, 9175 bytes)
[2019-01-27 23:45:26] [task-result-getter-0] INFO  TaskSetManager:54 - Finished task 141.0 in stage 0.0 (TID 141) in 62266 ms on himrod-12 (executor 5) (5/1971)
[2019-01-27 23:45:26] [dispatcher-event-loop-19] INFO  TaskSetManager:54 - Starting task 149.0 in stage 0.0 (TID 149, himrod-18, executor 9, partition 149, RACK_LOCAL, 9175 bytes)
[2019-01-27 23:45:26] [task-result-getter-1] INFO  TaskSetManager:54 - Finished task 117.0 in stage 0.0 (TID 117) in 62582 ms on himrod-18 (executor 9) (6/1971)
[2019-01-27 23:45:26] [dispatcher-event-loop-16] INFO  TaskSetManager:54 - Starting task 150.0 in stage 0.0 (TID 150, himrod-12, executor 5, partition 150, RACK_LOCAL, 9175 bytes)
[2019-01-27 23:45:26] [task-result-getter-2] INFO  TaskSetManager:54 - Finished task 42.0 in stage 0.0 (TID 42) in 62675 ms on himrod-12 (executor 5) (7/1971)
[2019-01-27 23:45:26] [dispatcher-event-loop-22] INFO  TaskSetManager:54 - Starting task 151.0 in stage 0.0 (TID 151, himrod-11, executor 3, partition 151, RACK_LOCAL, 9175 bytes)
[2019-01-27 23:45:26] [task-result-getter-3] INFO  TaskSetManager:54 - Finished task 30.0 in stage 0.0 (TID 30) in 62726 ms on himrod-11 (executor 3) (8/1971)
[2019-01-27 23:45:26] [dispatcher-event-loop-30] INFO  TaskSetManager:54 - Starting task 152.0 in stage 0.0 (TID 152, himrod-11, executor 3, partition 152, RACK_LOCAL, 9175 bytes)
[2019-01-27 23:45:26] [task-result-getter-0] INFO  TaskSetManager:54 - Finished task 138.0 in stage 0.0 (TID 138) in 62810 ms on himrod-11 (executor 3) (9/1971)
[2019-01-27 23:45:26] [dispatcher-event-loop-28] INFO  TaskSetManager:54 - Starting task 153.0 in stage 0.0 (TID 153, himrod-18, executor 9, partition 153, RACK_LOCAL, 9175 bytes)
[2019-01-27 23:45:26] [task-result-getter-1] INFO  TaskSetManager:54 - Finished task 63.0 in stage 0.0 (TID 63) in 63085 ms on himrod-18 (executor 9) (10/1971)
[2019-01-27 23:45:26] [dispatcher-event-loop-0] INFO  TaskSetManager:54 - Starting task 154.0 in stage 0.0 (TID 154, himrod-18, executor 9, partition 154, RACK_LOCAL, 9175 bytes)
[2019-01-27 23:45:26] [task-result-getter-2] INFO  TaskSetManager:54 - Finished task 36.0 in stage 0.0 (TID 36) in 63170 ms on himrod-18 (executor 9) (11/1971)
[2019-01-27 23:45:26] [dispatcher-event-loop-1] INFO  TaskSetManager:54 - Starting task 155.0 in stage 0.0 (TID 155, himrod-12, executor 5, partition 155, RACK_LOCAL, 9175 bytes)
[2019-01-27 23:45:26] [task-result-getter-3] INFO  TaskSetManager:54 - Finished task 114.0 in stage 0.0 (TID 114) in 63123 ms on himrod-12 (executor 5) (12/1971)
[2019-01-27 23:45:27] [dispatcher-event-loop-10] INFO  TaskSetManager:54 - Starting task 156.0 in stage 0.0 (TID 156, himrod-18, executor 9, partition 156, RACK_LOCAL, 9175 bytes)
[2019-01-27 23:45:27] [task-result-getter-0] INFO  TaskSetManager:54 - Finished task 126.0 in stage 0.0 (TID 126) in 63193 ms on himrod-18 (executor 9) (13/1971)
[2019-01-27 23:45:27] [dispatcher-event-loop-8] INFO  TaskSetManager:54 - Starting task 157.0 in stage 0.0 (TID 157, himrod-12, executor 5, partition 157, RACK_LOCAL, 9175 bytes)
[2019-01-27 23:45:27] [task-result-getter-1] INFO  TaskSetManager:54 - Finished task 87.0 in stage 0.0 (TID 87) in 63278 ms on himrod-12 (executor 5) (14/1971)
[2019-01-27 23:45:27] [dispatcher-event-loop-29] INFO  TaskSetManager:54 - Starting task 158.0 in stage 0.0 (TID 158, himrod-12, executor 5, partition 158, RACK_LOCAL, 9175 bytes)
[2019-01-27 23:45:27] [task-result-getter-2] INFO  TaskSetManager:54 - Finished task 123.0 in stage 0.0 (TID 123) in 63320 ms on himrod-12 (executor 5) (15/1971)
[2019-01-27 23:45:27] [dispatcher-event-loop-31] INFO  TaskSetManager:54 - Starting task 159.0 in stage 0.0 (TID 159, himrod-19, executor 4, partition 159, RACK_LOCAL, 9175 bytes)
[2019-01-27 23:45:27] [task-result-getter-3] INFO  TaskSetManager:54 - Finished task 122.0 in stage 0.0 (TID 122) in 63352 ms on himrod-19 (executor 4) (16/1971)
[2019-01-27 23:45:27] [dispatcher-event-loop-5] INFO  TaskSetManager:54 - Starting task 160.0 in stage 0.0 (TID 160, himrod-15, executor 6, partition 160, RACK_LOCAL, 9175 bytes)
[2019-01-27 23:45:27] [task-result-getter-0] INFO  TaskSetManager:54 - Finished task 116.0 in stage 0.0 (TID 116) in 63370 ms on himrod-15 (executor 6) (17/1971)
[2019-01-27 23:45:27] [dispatcher-event-loop-25] INFO  TaskSetManager:54 - Starting task 161.0 in stage 0.0 (TID 161, himrod-11, executor 3, partition 161, RACK_LOCAL, 9175 bytes)
[2019-01-27 23:45:27] [task-result-getter-1] INFO  TaskSetManager:54 - Finished task 39.0 in stage 0.0 (TID 39) in 63488 ms on himrod-11 (executor 3) (18/1971)
[2019-01-27 23:45:27] [dispatcher-event-loop-2] INFO  TaskSetManager:54 - Starting task 162.0 in stage 0.0 (TID 162, himrod-19, executor 4, partition 162, RACK_LOCAL, 9175 bytes)
[2019-01-27 23:45:27] [task-result-getter-2] INFO  TaskSetManager:54 - Finished task 5.0 in stage 0.0 (TID 5) in 63636 ms on himrod-19 (executor 4) (19/1971)
[2019-01-27 23:45:27] [dispatcher-event-loop-13] INFO  TaskSetManager:54 - Starting task 163.0 in stage 0.0 (TID 163, himrod-16, executor 2, partition 163, RACK_LOCAL, 9175 bytes)
[2019-01-27 23:45:27] [task-result-getter-3] INFO  TaskSetManager:54 - Finished task 56.0 in stage 0.0 (TID 56) in 63595 ms on himrod-16 (executor 2) (20/1971)
[2019-01-27 23:45:27] [dispatcher-event-loop-14] INFO  TaskSetManager:54 - Starting task 164.0 in stage 0.0 (TID 164, himrod-18, executor 9, partition 164, RACK_LOCAL, 9175 bytes)
[2019-01-27 23:45:27] [task-result-getter-0] INFO  TaskSetManager:54 - Finished task 108.0 in stage 0.0 (TID 108) in 63650 ms on himrod-18 (executor 9) (21/1971)
[2019-01-27 23:45:27] [dispatcher-event-loop-23] INFO  TaskSetManager:54 - Starting task 165.0 in stage 0.0 (TID 165, himrod-11, executor 3, partition 165, RACK_LOCAL, 9175 bytes)
[2019-01-27 23:45:27] [task-result-getter-1] INFO  TaskSetManager:54 - Finished task 3.0 in stage 0.0 (TID 3) in 63821 ms on himrod-11 (executor 3) (22/1971)
[2019-01-27 23:45:27] [dispatcher-event-loop-27] INFO  TaskSetManager:54 - Starting task 166.0 in stage 0.0 (TID 166, himrod-18, executor 9, partition 166, RACK_LOCAL, 9175 bytes)
[2019-01-27 23:45:27] [task-result-getter-2] INFO  TaskSetManager:54 - Finished task 135.0 in stage 0.0 (TID 135) in 63722 ms on himrod-18 (executor 9) (23/1971)
[2019-01-27 23:45:27] [dispatcher-event-loop-24] INFO  TaskSetManager:54 - Starting task 167.0 in stage 0.0 (TID 167, himrod-16, executor 2, partition 167, RACK_LOCAL, 9175 bytes)
[2019-01-27 23:45:27] [task-result-getter-3] INFO  TaskSetManager:54 - Finished task 128.0 in stage 0.0 (TID 128) in 63756 ms on himrod-16 (executor 2) (24/1971)
[2019-01-27 23:45:27] [dispatcher-event-loop-20] INFO  TaskSetManager:54 - Starting task 168.0 in stage 0.0 (TID 168, himrod-14, executor 8, partition 168, RACK_LOCAL, 9175 bytes)
[2019-01-27 23:45:27] [task-result-getter-0] INFO  TaskSetManager:54 - Finished task 106.0 in stage 0.0 (TID 106) in 63807 ms on himrod-14 (executor 8) (25/1971)
[2019-01-27 23:45:27] [dispatcher-event-loop-4] INFO  TaskSetManager:54 - Starting task 169.0 in stage 0.0 (TID 169, himrod-15, executor 6, partition 169, RACK_LOCAL, 9175 bytes)
[2019-01-27 23:45:27] [task-result-getter-1] INFO  TaskSetManager:54 - Finished task 107.0 in stage 0.0 (TID 107) in 63912 ms on himrod-15 (executor 6) (26/1971)
[2019-01-27 23:45:27] [dispatcher-event-loop-0] INFO  TaskSetManager:54 - Starting task 170.0 in stage 0.0 (TID 170, himrod-16, executor 2, partition 170, RACK_LOCAL, 9175 bytes)
[2019-01-27 23:45:27] [task-result-getter-2] INFO  TaskSetManager:54 - Finished task 29.0 in stage 0.0 (TID 29) in 63992 ms on himrod-16 (executor 2) (27/1971)
[2019-01-27 23:45:27] [dispatcher-event-loop-1] INFO  TaskSetManager:54 - Starting task 171.0 in stage 0.0 (TID 171, himrod-13, executor 1, partition 171, RACK_LOCAL, 9175 bytes)
[2019-01-27 23:45:27] [task-result-getter-3] INFO  TaskSetManager:54 - Finished task 64.0 in stage 0.0 (TID 64) in 64077 ms on himrod-13 (executor 1) (28/1971)
[2019-01-27 23:45:27] [dispatcher-event-loop-10] INFO  TaskSetManager:54 - Starting task 172.0 in stage 0.0 (TID 172, himrod-13, executor 1, partition 172, RACK_LOCAL, 9175 bytes)
[2019-01-27 23:45:27] [task-result-getter-0] INFO  TaskSetManager:54 - Finished task 127.0 in stage 0.0 (TID 127) in 64053 ms on himrod-13 (executor 1) (29/1971)
[2019-01-27 23:45:27] [dispatcher-event-loop-26] INFO  TaskSetManager:54 - Starting task 173.0 in stage 0.0 (TID 173, himrod-11, executor 3, partition 173, RACK_LOCAL, 9175 bytes)
[2019-01-27 23:45:27] [task-result-getter-1] INFO  TaskSetManager:54 - Finished task 120.0 in stage 0.0 (TID 120) in 64135 ms on himrod-11 (executor 3) (30/1971)
[2019-01-27 23:45:28] [dispatcher-event-loop-3] INFO  TaskSetManager:54 - Starting task 174.0 in stage 0.0 (TID 174, himrod-12, executor 5, partition 174, RACK_LOCAL, 9175 bytes)
[2019-01-27 23:45:28] [task-result-getter-2] INFO  TaskSetManager:54 - Finished task 78.0 in stage 0.0 (TID 78) in 64233 ms on himrod-12 (executor 5) (31/1971)
[2019-01-27 23:45:28] [dispatcher-event-loop-12] INFO  TaskSetManager:54 - Starting task 175.0 in stage 0.0 (TID 175, himrod-15, executor 6, partition 175, RACK_LOCAL, 9175 bytes)
[2019-01-27 23:45:28] [task-result-getter-3] INFO  TaskSetManager:54 - Finished task 8.0 in stage 0.0 (TID 8) in 64330 ms on himrod-15 (executor 6) (32/1971)
[2019-01-27 23:45:28] [dispatcher-event-loop-11] INFO  TaskSetManager:54 - Starting task 176.0 in stage 0.0 (TID 176, himrod-18, executor 9, partition 176, RACK_LOCAL, 9175 bytes)
[2019-01-27 23:45:28] [task-result-getter-0] INFO  TaskSetManager:54 - Finished task 45.0 in stage 0.0 (TID 45) in 64338 ms on himrod-18 (executor 9) (33/1971)
[2019-01-27 23:45:28] [dispatcher-event-loop-18] INFO  TaskSetManager:54 - Starting task 177.0 in stage 0.0 (TID 177, himrod-12, executor 5, partition 177, RACK_LOCAL, 9175 bytes)
[2019-01-27 23:45:28] [task-result-getter-1] INFO  TaskSetManager:54 - Finished task 69.0 in stage 0.0 (TID 69) in 64385 ms on himrod-12 (executor 5) (34/1971)
[2019-01-27 23:45:28] [dispatcher-event-loop-15] INFO  TaskSetManager:54 - Starting task 178.0 in stage 0.0 (TID 178, himrod-18, executor 9, partition 178, RACK_LOCAL, 9175 bytes)
[2019-01-27 23:45:28] [task-result-getter-2] INFO  TaskSetManager:54 - Finished task 0.0 in stage 0.0 (TID 0) in 64555 ms on himrod-18 (executor 9) (35/1971)
[2019-01-27 23:45:28] [dispatcher-event-loop-17] INFO  TaskSetManager:54 - Starting task 179.0 in stage 0.0 (TID 179, himrod-15, executor 6, partition 179, RACK_LOCAL, 9175 bytes)
[2019-01-27 23:45:28] [task-result-getter-3] INFO  TaskSetManager:54 - Finished task 80.0 in stage 0.0 (TID 80) in 64443 ms on himrod-15 (executor 6) (36/1971)
[2019-01-27 23:45:28] [dispatcher-event-loop-17] INFO  TaskSetManager:54 - Starting task 180.0 in stage 0.0 (TID 180, himrod-12, executor 5, partition 180, RACK_LOCAL, 9175 bytes)
[2019-01-27 23:45:28] [task-result-getter-0] INFO  TaskSetManager:54 - Finished task 51.0 in stage 0.0 (TID 51) in 64471 ms on himrod-12 (executor 5) (37/1971)
[2019-01-27 23:45:28] [dispatcher-event-loop-16] INFO  TaskSetManager:54 - Starting task 181.0 in stage 0.0 (TID 181, himrod-15, executor 6, partition 181, RACK_LOCAL, 9175 bytes)
[2019-01-27 23:45:28] [task-result-getter-1] INFO  TaskSetManager:54 - Finished task 17.0 in stage 0.0 (TID 17) in 64627 ms on himrod-15 (executor 6) (38/1971)
[2019-01-27 23:45:28] [dispatcher-event-loop-22] INFO  TaskSetManager:54 - Starting task 182.0 in stage 0.0 (TID 182, himrod-15, executor 6, partition 182, RACK_LOCAL, 9175 bytes)
[2019-01-27 23:45:28] [task-result-getter-2] INFO  TaskSetManager:54 - Finished task 62.0 in stage 0.0 (TID 62) in 64624 ms on himrod-15 (executor 6) (39/1971)
[2019-01-27 23:45:28] [dispatcher-event-loop-30] INFO  TaskSetManager:54 - Starting task 183.0 in stage 0.0 (TID 183, himrod-12, executor 5, partition 183, RACK_LOCAL, 9175 bytes)
[2019-01-27 23:45:28] [task-result-getter-3] INFO  TaskSetManager:54 - Finished task 6.0 in stage 0.0 (TID 6) in 64753 ms on himrod-12 (executor 5) (40/1971)
[2019-01-27 23:45:28] [dispatcher-event-loop-28] INFO  TaskSetManager:54 - Starting task 184.0 in stage 0.0 (TID 184, himrod-14, executor 8, partition 184, RACK_LOCAL, 9175 bytes)
[2019-01-27 23:45:28] [task-result-getter-0] INFO  TaskSetManager:54 - Finished task 142.0 in stage 0.0 (TID 142) in 64617 ms on himrod-14 (executor 8) (41/1971)
[2019-01-27 23:45:28] [dispatcher-event-loop-6] INFO  TaskSetManager:54 - Starting task 185.0 in stage 0.0 (TID 185, himrod-11, executor 3, partition 185, RACK_LOCAL, 9175 bytes)
[2019-01-27 23:45:28] [task-result-getter-1] INFO  TaskSetManager:54 - Finished task 21.0 in stage 0.0 (TID 21) in 64793 ms on himrod-11 (executor 3) (42/1971)
[2019-01-27 23:45:28] [dispatcher-event-loop-7] INFO  TaskSetManager:54 - Starting task 186.0 in stage 0.0 (TID 186, himrod-19, executor 4, partition 186, RACK_LOCAL, 9175 bytes)
[2019-01-27 23:45:28] [task-result-getter-2] INFO  TaskSetManager:54 - Finished task 23.0 in stage 0.0 (TID 23) in 64852 ms on himrod-19 (executor 4) (43/1971)
[2019-01-27 23:45:28] [dispatcher-event-loop-21] INFO  TaskSetManager:54 - Starting task 187.0 in stage 0.0 (TID 187, himrod-13, executor 1, partition 187, RACK_LOCAL, 9175 bytes)
[2019-01-27 23:45:28] [task-result-getter-3] INFO  TaskSetManager:54 - Finished task 82.0 in stage 0.0 (TID 82) in 64850 ms on himrod-13 (executor 1) (44/1971)
[2019-01-27 23:45:28] [dispatcher-event-loop-9] INFO  TaskSetManager:54 - Starting task 188.0 in stage 0.0 (TID 188, himrod-13, executor 1, partition 188, RACK_LOCAL, 9175 bytes)
[2019-01-27 23:45:28] [task-result-getter-0] INFO  TaskSetManager:54 - Finished task 37.0 in stage 0.0 (TID 37) in 64901 ms on himrod-13 (executor 1) (45/1971)
[2019-01-27 23:45:28] [dispatcher-event-loop-9] INFO  TaskSetManager:54 - Starting task 189.0 in stage 0.0 (TID 189, himrod-14, executor 8, partition 189, RACK_LOCAL, 9175 bytes)
[2019-01-27 23:45:28] [task-result-getter-1] INFO  TaskSetManager:54 - Finished task 115.0 in stage 0.0 (TID 115) in 64831 ms on himrod-14 (executor 8) (46/1971)
[2019-01-27 23:45:28] [dispatcher-event-loop-9] INFO  TaskSetManager:54 - Starting task 190.0 in stage 0.0 (TID 190, himrod-14, executor 8, partition 190, RACK_LOCAL, 9175 bytes)
[2019-01-27 23:45:28] [task-result-getter-2] INFO  TaskSetManager:54 - Finished task 25.0 in stage 0.0 (TID 25) in 64918 ms on himrod-14 (executor 8) (47/1971)
[2019-01-27 23:45:28] [dispatcher-event-loop-12] INFO  TaskSetManager:54 - Starting task 191.0 in stage 0.0 (TID 191, himrod-19, executor 4, partition 191, RACK_LOCAL, 9175 bytes)
[2019-01-27 23:45:28] [task-result-getter-3] INFO  TaskSetManager:54 - Finished task 50.0 in stage 0.0 (TID 50) in 64933 ms on himrod-19 (executor 4) (48/1971)
[2019-01-27 23:45:28] [dispatcher-event-loop-11] INFO  TaskSetManager:54 - Starting task 192.0 in stage 0.0 (TID 192, himrod-15, executor 6, partition 192, RACK_LOCAL, 9175 bytes)
[2019-01-27 23:45:28] [task-result-getter-0] INFO  TaskSetManager:54 - Finished task 125.0 in stage 0.0 (TID 125) in 64925 ms on himrod-15 (executor 6) (49/1971)
[2019-01-27 23:45:28] [dispatcher-event-loop-18] INFO  TaskSetManager:54 - Starting task 193.0 in stage 0.0 (TID 193, himrod-16, executor 2, partition 193, RACK_LOCAL, 9175 bytes)
[2019-01-27 23:45:28] [task-result-getter-1] INFO  TaskSetManager:54 - Finished task 101.0 in stage 0.0 (TID 101) in 65009 ms on himrod-16 (executor 2) (50/1971)
[2019-01-27 23:45:28] [dispatcher-event-loop-15] INFO  TaskSetManager:54 - Starting task 194.0 in stage 0.0 (TID 194, himrod-12, executor 5, partition 194, RACK_LOCAL, 9175 bytes)
[2019-01-27 23:45:28] [task-result-getter-2] INFO  TaskSetManager:54 - Finished task 33.0 in stage 0.0 (TID 33) in 65099 ms on himrod-12 (executor 5) (51/1971)
[2019-01-27 23:45:28] [dispatcher-event-loop-14] INFO  TaskSetManager:54 - Starting task 195.0 in stage 0.0 (TID 195, himrod-14, executor 8, partition 195, RACK_LOCAL, 9175 bytes)
[2019-01-27 23:45:28] [task-result-getter-3] INFO  TaskSetManager:54 - Finished task 124.0 in stage 0.0 (TID 124) in 65022 ms on himrod-14 (executor 8) (52/1971)
[2019-01-27 23:45:28] [dispatcher-event-loop-19] INFO  TaskSetManager:54 - Starting task 196.0 in stage 0.0 (TID 196, himrod-11, executor 3, partition 196, RACK_LOCAL, 9175 bytes)
[2019-01-27 23:45:28] [task-result-getter-0] INFO  TaskSetManager:54 - Finished task 48.0 in stage 0.0 (TID 48) in 65123 ms on himrod-11 (executor 3) (53/1971)
[2019-01-27 23:45:28] [dispatcher-event-loop-27] INFO  TaskSetManager:54 - Starting task 197.0 in stage 0.0 (TID 197, himrod-19, executor 4, partition 197, RACK_LOCAL, 9175 bytes)
[2019-01-27 23:45:28] [task-result-getter-1] INFO  TaskSetManager:54 - Finished task 86.0 in stage 0.0 (TID 86) in 65140 ms on himrod-19 (executor 4) (54/1971)
[2019-01-27 23:45:28] [dispatcher-event-loop-24] INFO  TaskSetManager:54 - Starting task 198.0 in stage 0.0 (TID 198, himrod-11, executor 3, partition 198, RACK_LOCAL, 9175 bytes)
[2019-01-27 23:45:28] [task-result-getter-2] INFO  TaskSetManager:54 - Finished task 84.0 in stage 0.0 (TID 84) in 65156 ms on himrod-11 (executor 3) (55/1971)
[2019-01-27 23:45:29] [dispatcher-event-loop-20] INFO  TaskSetManager:54 - Starting task 199.0 in stage 0.0 (TID 199, himrod-19, executor 4, partition 199, RACK_LOCAL, 9175 bytes)
[2019-01-27 23:45:29] [task-result-getter-3] INFO  TaskSetManager:54 - Finished task 32.0 in stage 0.0 (TID 32) in 65275 ms on himrod-19 (executor 4) (56/1971)
[2019-01-27 23:45:29] [dispatcher-event-loop-4] INFO  TaskSetManager:54 - Starting task 200.0 in stage 0.0 (TID 200, himrod-16, executor 2, partition 200, RACK_LOCAL, 9175 bytes)
[2019-01-27 23:45:29] [task-result-getter-0] INFO  TaskSetManager:54 - Finished task 92.0 in stage 0.0 (TID 92) in 65264 ms on himrod-16 (executor 2) (57/1971)
[2019-01-27 23:45:29] [dispatcher-event-loop-0] INFO  TaskSetManager:54 - Starting task 201.0 in stage 0.0 (TID 201, himrod-16, executor 2, partition 201, RACK_LOCAL, 9175 bytes)
[2019-01-27 23:45:29] [task-result-getter-1] INFO  TaskSetManager:54 - Finished task 74.0 in stage 0.0 (TID 74) in 65296 ms on himrod-16 (executor 2) (58/1971)
[2019-01-27 23:45:29] [dispatcher-event-loop-1] INFO  TaskSetManager:54 - Starting task 202.0 in stage 0.0 (TID 202, himrod-18, executor 9, partition 202, RACK_LOCAL, 9175 bytes)
[2019-01-27 23:45:29] [task-result-getter-2] INFO  TaskSetManager:54 - Finished task 54.0 in stage 0.0 (TID 54) in 65350 ms on himrod-18 (executor 9) (59/1971)
[2019-01-27 23:45:29] [dispatcher-event-loop-10] INFO  TaskSetManager:54 - Starting task 203.0 in stage 0.0 (TID 203, himrod-11, executor 3, partition 203, RACK_LOCAL, 9175 bytes)
[2019-01-27 23:45:29] [task-result-getter-3] INFO  TaskSetManager:54 - Finished task 75.0 in stage 0.0 (TID 75) in 65375 ms on himrod-11 (executor 3) (60/1971)
[2019-01-27 23:45:29] [dispatcher-event-loop-26] INFO  TaskSetManager:54 - Starting task 204.0 in stage 0.0 (TID 204, himrod-16, executor 2, partition 204, RACK_LOCAL, 9175 bytes)
[2019-01-27 23:45:29] [task-result-getter-0] INFO  TaskSetManager:54 - Finished task 110.0 in stage 0.0 (TID 110) in 65380 ms on himrod-16 (executor 2) (61/1971)
[2019-01-27 23:45:29] [dispatcher-event-loop-29] INFO  TaskSetManager:54 - Starting task 205.0 in stage 0.0 (TID 205, himrod-15, executor 6, partition 205, RACK_LOCAL, 9175 bytes)
[2019-01-27 23:45:29] [task-result-getter-1] INFO  TaskSetManager:54 - Finished task 71.0 in stage 0.0 (TID 71) in 65445 ms on himrod-15 (executor 6) (62/1971)
[2019-01-27 23:45:29] [dispatcher-event-loop-31] INFO  TaskSetManager:54 - Starting task 206.0 in stage 0.0 (TID 206, himrod-19, executor 4, partition 206, RACK_LOCAL, 9175 bytes)
[2019-01-27 23:45:29] [task-result-getter-2] INFO  TaskSetManager:54 - Finished task 41.0 in stage 0.0 (TID 41) in 65498 ms on himrod-19 (executor 4) (63/1971)
[2019-01-27 23:45:29] [dispatcher-event-loop-5] INFO  TaskSetManager:54 - Starting task 207.0 in stage 0.0 (TID 207, himrod-16, executor 2, partition 207, RACK_LOCAL, 9175 bytes)
[2019-01-27 23:45:29] [task-result-getter-3] INFO  TaskSetManager:54 - Finished task 119.0 in stage 0.0 (TID 119) in 65467 ms on himrod-16 (executor 2) (64/1971)
[2019-01-27 23:45:29] [dispatcher-event-loop-25] INFO  TaskSetManager:54 - Starting task 208.0 in stage 0.0 (TID 208, himrod-15, executor 6, partition 208, RACK_LOCAL, 9175 bytes)
[2019-01-27 23:45:29] [task-result-getter-0] INFO  TaskSetManager:54 - Finished task 44.0 in stage 0.0 (TID 44) in 65555 ms on himrod-15 (executor 6) (65/1971)
[2019-01-27 23:45:29] [dispatcher-event-loop-2] INFO  TaskSetManager:54 - Starting task 209.0 in stage 0.0 (TID 209, himrod-19, executor 4, partition 209, RACK_LOCAL, 9175 bytes)
[2019-01-27 23:45:29] [task-result-getter-1] INFO  TaskSetManager:54 - Finished task 113.0 in stage 0.0 (TID 113) in 65540 ms on himrod-19 (executor 4) (66/1971)
[2019-01-27 23:45:29] [dispatcher-event-loop-13] INFO  TaskSetManager:54 - Starting task 210.0 in stage 0.0 (TID 210, himrod-14, executor 8, partition 210, RACK_LOCAL, 9175 bytes)
[2019-01-27 23:45:29] [task-result-getter-2] INFO  TaskSetManager:54 - Finished task 61.0 in stage 0.0 (TID 61) in 65719 ms on himrod-14 (executor 8) (67/1971)
[2019-01-27 23:45:29] [dispatcher-event-loop-17] INFO  TaskSetManager:54 - Starting task 211.0 in stage 0.0 (TID 211, himrod-14, executor 8, partition 211, RACK_LOCAL, 9175 bytes)
[2019-01-27 23:45:29] [task-result-getter-3] INFO  TaskSetManager:54 - Finished task 52.0 in stage 0.0 (TID 52) in 65845 ms on himrod-14 (executor 8) (68/1971)
[2019-01-27 23:45:29] [dispatcher-event-loop-23] INFO  TaskSetManager:54 - Starting task 212.0 in stage 0.0 (TID 212, himrod-19, executor 4, partition 212, RACK_LOCAL, 9175 bytes)
[2019-01-27 23:45:29] [task-result-getter-0] INFO  TaskSetManager:54 - Finished task 140.0 in stage 0.0 (TID 140) in 65787 ms on himrod-19 (executor 4) (69/1971)
[2019-01-27 23:45:29] [dispatcher-event-loop-27] INFO  TaskSetManager:54 - Starting task 213.0 in stage 0.0 (TID 213, himrod-18, executor 9, partition 213, RACK_LOCAL, 9175 bytes)
[2019-01-27 23:45:29] [task-result-getter-1] INFO  TaskSetManager:54 - Finished task 27.0 in stage 0.0 (TID 27) in 65967 ms on himrod-18 (executor 9) (70/1971)
[2019-01-27 23:45:29] [dispatcher-event-loop-24] INFO  TaskSetManager:54 - Starting task 214.0 in stage 0.0 (TID 214, himrod-19, executor 4, partition 214, RACK_LOCAL, 9175 bytes)
[2019-01-27 23:45:29] [task-result-getter-2] INFO  TaskSetManager:54 - Finished task 59.0 in stage 0.0 (TID 59) in 65952 ms on himrod-19 (executor 4) (71/1971)
[2019-01-27 23:45:30] [dispatcher-event-loop-28] INFO  TaskSetManager:54 - Starting task 215.0 in stage 0.0 (TID 215, himrod-12, executor 5, partition 215, RACK_LOCAL, 9175 bytes)
[2019-01-27 23:45:30] [task-result-getter-3] INFO  TaskSetManager:54 - Finished task 60.0 in stage 0.0 (TID 60) in 66200 ms on himrod-12 (executor 5) (72/1971)
[2019-01-27 23:45:30] [dispatcher-event-loop-6] INFO  TaskSetManager:54 - Starting task 216.0 in stage 0.0 (TID 216, himrod-16, executor 2, partition 216, RACK_LOCAL, 9175 bytes)
[2019-01-27 23:45:30] [task-result-getter-0] INFO  TaskSetManager:54 - Finished task 47.0 in stage 0.0 (TID 47) in 66227 ms on himrod-16 (executor 2) (73/1971)
[2019-01-27 23:45:30] [dispatcher-event-loop-7] INFO  TaskSetManager:54 - Starting task 217.0 in stage 0.0 (TID 217, himrod-14, executor 8, partition 217, RACK_LOCAL, 9175 bytes)
[2019-01-27 23:45:30] [task-result-getter-1] INFO  TaskSetManager:54 - Finished task 16.0 in stage 0.0 (TID 16) in 66324 ms on himrod-14 (executor 8) (74/1971)
[2019-01-27 23:45:30] [dispatcher-event-loop-21] INFO  TaskSetManager:54 - Starting task 218.0 in stage 0.0 (TID 218, himrod-18, executor 9, partition 218, RACK_LOCAL, 9175 bytes)
[2019-01-27 23:45:30] [task-result-getter-2] INFO  TaskSetManager:54 - Finished task 99.0 in stage 0.0 (TID 99) in 66346 ms on himrod-18 (executor 9) (75/1971)
[2019-01-27 23:45:30] [dispatcher-event-loop-8] INFO  TaskSetManager:54 - Starting task 219.0 in stage 0.0 (TID 219, himrod-12, executor 5, partition 219, RACK_LOCAL, 9173 bytes)
[2019-01-27 23:45:30] [task-result-getter-3] INFO  TaskSetManager:54 - Finished task 24.0 in stage 0.0 (TID 24) in 66539 ms on himrod-12 (executor 5) (76/1971)
[2019-01-27 23:45:30] [dispatcher-event-loop-9] INFO  TaskSetManager:54 - Starting task 220.0 in stage 0.0 (TID 220, himrod-13, executor 1, partition 220, RACK_LOCAL, 9173 bytes)
[2019-01-27 23:45:30] [task-result-getter-0] INFO  TaskSetManager:54 - Finished task 91.0 in stage 0.0 (TID 91) in 66558 ms on himrod-13 (executor 1) (77/1971)
[2019-01-27 23:45:30] [dispatcher-event-loop-3] INFO  TaskSetManager:54 - Starting task 221.0 in stage 0.0 (TID 221, himrod-19, executor 4, partition 221, RACK_LOCAL, 9173 bytes)
[2019-01-27 23:45:30] [task-result-getter-1] INFO  TaskSetManager:54 - Finished task 68.0 in stage 0.0 (TID 68) in 66687 ms on himrod-19 (executor 4) (78/1971)
[2019-01-27 23:45:30] [dispatcher-event-loop-12] INFO  TaskSetManager:54 - Starting task 222.0 in stage 0.0 (TID 222, himrod-16, executor 2, partition 222, RACK_LOCAL, 9173 bytes)
[2019-01-27 23:45:30] [task-result-getter-2] INFO  TaskSetManager:54 - Finished task 20.0 in stage 0.0 (TID 20) in 66772 ms on himrod-16 (executor 2) (79/1971)
[2019-01-27 23:45:30] [dispatcher-event-loop-11] INFO  TaskSetManager:54 - Starting task 223.0 in stage 0.0 (TID 223, himrod-16, executor 2, partition 223, RACK_LOCAL, 9173 bytes)
[2019-01-27 23:45:30] [task-result-getter-3] INFO  TaskSetManager:54 - Finished task 137.0 in stage 0.0 (TID 137) in 66753 ms on himrod-16 (executor 2) (80/1971)
[2019-01-27 23:45:30] [dispatcher-event-loop-11] INFO  TaskSetManager:54 - Starting task 224.0 in stage 0.0 (TID 224, himrod-15, executor 6, partition 224, RACK_LOCAL, 9173 bytes)
[2019-01-27 23:45:30] [task-result-getter-0] INFO  TaskSetManager:54 - Finished task 134.0 in stage 0.0 (TID 134) in 66757 ms on himrod-15 (executor 6) (81/1971)
[2019-01-27 23:45:30] [dispatcher-event-loop-15] INFO  TaskSetManager:54 - Starting task 225.0 in stage 0.0 (TID 225, himrod-18, executor 9, partition 225, RACK_LOCAL, 9173 bytes)
[2019-01-27 23:45:30] [task-result-getter-1] INFO  TaskSetManager:54 - Finished task 90.0 in stage 0.0 (TID 90) in 67056 ms on himrod-18 (executor 9) (82/1971)
[2019-01-27 23:45:30] [dispatcher-event-loop-17] INFO  TaskSetManager:54 - Starting task 226.0 in stage 0.0 (TID 226, himrod-13, executor 1, partition 226, RACK_LOCAL, 9173 bytes)
[2019-01-27 23:45:30] [task-result-getter-2] INFO  TaskSetManager:54 - Finished task 55.0 in stage 0.0 (TID 55) in 67177 ms on himrod-13 (executor 1) (83/1971)
[2019-01-27 23:45:31] [dispatcher-event-loop-23] INFO  TaskSetManager:54 - Starting task 227.0 in stage 0.0 (TID 227, himrod-17, executor 7, partition 227, RACK_LOCAL, 9173 bytes)
[2019-01-27 23:45:31] [task-result-getter-3] INFO  TaskSetManager:54 - Finished task 103.0 in stage 0.0 (TID 103) in 67185 ms on himrod-17 (executor 7) (84/1971)
[2019-01-27 23:45:31] [dispatcher-event-loop-27] INFO  TaskSetManager:54 - Starting task 228.0 in stage 0.0 (TID 228, himrod-13, executor 1, partition 228, RACK_LOCAL, 9173 bytes)
[2019-01-27 23:45:31] [task-result-getter-0] INFO  TaskSetManager:54 - Finished task 1.0 in stage 0.0 (TID 1) in 67368 ms on himrod-13 (executor 1) (85/1971)
[2019-01-27 23:45:31] [dispatcher-event-loop-24] INFO  TaskSetManager:54 - Starting task 229.0 in stage 0.0 (TID 229, himrod-13, executor 1, partition 229, RACK_LOCAL, 9174 bytes)
[2019-01-27 23:45:31] [task-result-getter-1] INFO  TaskSetManager:54 - Finished task 73.0 in stage 0.0 (TID 73) in 67369 ms on himrod-13 (executor 1) (86/1971)
[2019-01-27 23:45:31] [dispatcher-event-loop-20] INFO  TaskSetManager:54 - Starting task 230.0 in stage 0.0 (TID 230, himrod-12, executor 5, partition 230, RACK_LOCAL, 9174 bytes)
[2019-01-27 23:45:31] [task-result-getter-2] INFO  TaskSetManager:54 - Finished task 15.0 in stage 0.0 (TID 15) in 67502 ms on himrod-12 (executor 5) (87/1971)
[2019-01-27 23:45:31] [dispatcher-event-loop-4] INFO  TaskSetManager:54 - Starting task 231.0 in stage 0.0 (TID 231, himrod-17, executor 7, partition 231, RACK_LOCAL, 9174 bytes)
[2019-01-27 23:45:31] [task-result-getter-3] INFO  TaskSetManager:54 - Finished task 76.0 in stage 0.0 (TID 76) in 67817 ms on himrod-17 (executor 7) (88/1971)
[2019-01-27 23:45:31] [dispatcher-event-loop-0] INFO  TaskSetManager:54 - Starting task 232.0 in stage 0.0 (TID 232, himrod-14, executor 8, partition 232, RACK_LOCAL, 9174 bytes)
[2019-01-27 23:45:31] [task-result-getter-0] INFO  TaskSetManager:54 - Finished task 7.0 in stage 0.0 (TID 7) in 67951 ms on himrod-14 (executor 8) (89/1971)
[2019-01-27 23:45:31] [dispatcher-event-loop-1] INFO  TaskSetManager:54 - Starting task 233.0 in stage 0.0 (TID 233, himrod-16, executor 2, partition 233, RACK_LOCAL, 9174 bytes)
[2019-01-27 23:45:31] [task-result-getter-1] INFO  TaskSetManager:54 - Finished task 38.0 in stage 0.0 (TID 38) in 68173 ms on himrod-16 (executor 2) (90/1971)
[2019-01-27 23:45:32] [dispatcher-event-loop-8] INFO  TaskSetManager:54 - Starting task 234.0 in stage 0.0 (TID 234, himrod-16, executor 2, partition 234, RACK_LOCAL, 9174 bytes)
[2019-01-27 23:45:32] [task-result-getter-2] INFO  TaskSetManager:54 - Finished task 83.0 in stage 0.0 (TID 83) in 68267 ms on himrod-16 (executor 2) (91/1971)
[2019-01-27 23:45:32] [dispatcher-event-loop-9] INFO  TaskSetManager:54 - Starting task 235.0 in stage 0.0 (TID 235, himrod-13, executor 1, partition 235, RACK_LOCAL, 9174 bytes)
[2019-01-27 23:45:32] [task-result-getter-3] INFO  TaskSetManager:54 - Finished task 28.0 in stage 0.0 (TID 28) in 68353 ms on himrod-13 (executor 1) (92/1971)
[2019-01-27 23:45:32] [dispatcher-event-loop-3] INFO  TaskSetManager:54 - Starting task 236.0 in stage 0.0 (TID 236, himrod-19, executor 4, partition 236, RACK_LOCAL, 9174 bytes)
[2019-01-27 23:45:32] [task-result-getter-0] INFO  TaskSetManager:54 - Finished task 77.0 in stage 0.0 (TID 77) in 68313 ms on himrod-19 (executor 4) (93/1971)
[2019-01-27 23:45:32] [dispatcher-event-loop-12] INFO  TaskSetManager:54 - Starting task 237.0 in stage 0.0 (TID 237, himrod-17, executor 7, partition 237, RACK_LOCAL, 9174 bytes)
[2019-01-27 23:45:32] [task-result-getter-1] INFO  TaskSetManager:54 - Finished task 40.0 in stage 0.0 (TID 40) in 68358 ms on himrod-17 (executor 7) (94/1971)
[2019-01-27 23:45:32] [dispatcher-event-loop-25] INFO  TaskSetManager:54 - Starting task 238.0 in stage 0.0 (TID 238, himrod-17, executor 7, partition 238, RACK_LOCAL, 9174 bytes)
[2019-01-27 23:45:32] [task-result-getter-2] INFO  TaskSetManager:54 - Finished task 58.0 in stage 0.0 (TID 58) in 68499 ms on himrod-17 (executor 7) (95/1971)
[2019-01-27 23:45:32] [dispatcher-event-loop-11] INFO  TaskSetManager:54 - Starting task 239.0 in stage 0.0 (TID 239, himrod-15, executor 6, partition 239, RACK_LOCAL, 9174 bytes)
[2019-01-27 23:45:32] [task-result-getter-3] INFO  TaskSetManager:54 - Finished task 143.0 in stage 0.0 (TID 143) in 68427 ms on himrod-15 (executor 6) (96/1971)
[2019-01-27 23:45:32] [dispatcher-event-loop-15] INFO  TaskSetManager:54 - Starting task 240.0 in stage 0.0 (TID 240, himrod-17, executor 7, partition 240, RACK_LOCAL, 9174 bytes)
[2019-01-27 23:45:32] [task-result-getter-0] INFO  TaskSetManager:54 - Finished task 139.0 in stage 0.0 (TID 139) in 68509 ms on himrod-17 (executor 7) (97/1971)
[2019-01-27 23:45:32] [dispatcher-event-loop-14] INFO  TaskSetManager:54 - Starting task 241.0 in stage 0.0 (TID 241, himrod-11, executor 3, partition 241, RACK_LOCAL, 9174 bytes)
[2019-01-27 23:45:32] [task-result-getter-1] INFO  TaskSetManager:54 - Finished task 111.0 in stage 0.0 (TID 111) in 68571 ms on himrod-11 (executor 3) (98/1971)
[2019-01-27 23:45:32] [dispatcher-event-loop-19] INFO  TaskSetManager:54 - Starting task 242.0 in stage 0.0 (TID 242, himrod-11, executor 3, partition 242, RACK_LOCAL, 9174 bytes)
[2019-01-27 23:45:32] [task-result-getter-2] INFO  TaskSetManager:54 - Finished task 93.0 in stage 0.0 (TID 93) in 68648 ms on himrod-11 (executor 3) (99/1971)
[2019-01-27 23:45:32] [dispatcher-event-loop-16] INFO  TaskSetManager:54 - Starting task 243.0 in stage 0.0 (TID 243, himrod-13, executor 1, partition 243, RACK_LOCAL, 9174 bytes)
[2019-01-27 23:45:32] [task-result-getter-3] INFO  TaskSetManager:54 - Finished task 100.0 in stage 0.0 (TID 100) in 68735 ms on himrod-13 (executor 1) (100/1971)
[2019-01-27 23:45:32] [dispatcher-event-loop-22] INFO  TaskSetManager:54 - Starting task 244.0 in stage 0.0 (TID 244, himrod-14, executor 8, partition 244, RACK_LOCAL, 9174 bytes)
[2019-01-27 23:45:32] [task-result-getter-0] INFO  TaskSetManager:54 - Finished task 79.0 in stage 0.0 (TID 79) in 68816 ms on himrod-14 (executor 8) (101/1971)
[2019-01-27 23:45:32] [dispatcher-event-loop-24] INFO  TaskSetManager:54 - Starting task 245.0 in stage 0.0 (TID 245, himrod-17, executor 7, partition 245, RACK_LOCAL, 9174 bytes)
[2019-01-27 23:45:32] [task-result-getter-1] INFO  TaskSetManager:54 - Finished task 94.0 in stage 0.0 (TID 94) in 68901 ms on himrod-17 (executor 7) (102/1971)
[2019-01-27 23:45:32] [dispatcher-event-loop-20] INFO  TaskSetManager:54 - Starting task 246.0 in stage 0.0 (TID 246, himrod-19, executor 4, partition 246, RACK_LOCAL, 9174 bytes)
[2019-01-27 23:45:32] [task-result-getter-2] INFO  TaskSetManager:54 - Finished task 14.0 in stage 0.0 (TID 14) in 69043 ms on himrod-19 (executor 4) (103/1971)
[2019-01-27 23:45:32] [dispatcher-event-loop-4] INFO  TaskSetManager:54 - Starting task 247.0 in stage 0.0 (TID 247, himrod-17, executor 7, partition 247, RACK_LOCAL, 9174 bytes)
[2019-01-27 23:45:32] [task-result-getter-3] INFO  TaskSetManager:54 - Finished task 13.0 in stage 0.0 (TID 13) in 69057 ms on himrod-17 (executor 7) (104/1971)
[2019-01-27 23:45:32] [dispatcher-event-loop-7] INFO  TaskSetManager:54 - Starting task 248.0 in stage 0.0 (TID 248, himrod-19, executor 4, partition 248, RACK_LOCAL, 9174 bytes)
[2019-01-27 23:45:32] [task-result-getter-0] INFO  TaskSetManager:54 - Finished task 95.0 in stage 0.0 (TID 95) in 69007 ms on himrod-19 (executor 4) (105/1971)
[2019-01-27 23:45:32] [dispatcher-event-loop-1] INFO  TaskSetManager:54 - Starting task 249.0 in stage 0.0 (TID 249, himrod-16, executor 2, partition 249, RACK_LOCAL, 9174 bytes)
[2019-01-27 23:45:32] [task-result-getter-1] INFO  TaskSetManager:54 - Finished task 11.0 in stage 0.0 (TID 11) in 69102 ms on himrod-16 (executor 2) (106/1971)
[2019-01-27 23:45:32] [dispatcher-event-loop-8] INFO  TaskSetManager:54 - Starting task 250.0 in stage 0.0 (TID 250, himrod-13, executor 1, partition 250, RACK_LOCAL, 9174 bytes)
[2019-01-27 23:45:32] [task-result-getter-2] INFO  TaskSetManager:54 - Finished task 10.0 in stage 0.0 (TID 10) in 69141 ms on himrod-13 (executor 1) (107/1971)
[2019-01-27 23:45:32] [dispatcher-event-loop-9] INFO  TaskSetManager:54 - Starting task 251.0 in stage 0.0 (TID 251, himrod-14, executor 8, partition 251, RACK_LOCAL, 9174 bytes)
[2019-01-27 23:45:32] [task-result-getter-3] INFO  TaskSetManager:54 - Finished task 70.0 in stage 0.0 (TID 70) in 69113 ms on himrod-14 (executor 8) (108/1971)
[2019-01-27 23:45:33] [dispatcher-event-loop-31] INFO  TaskSetManager:54 - Starting task 252.0 in stage 0.0 (TID 252, himrod-13, executor 1, partition 252, RACK_LOCAL, 9174 bytes)
[2019-01-27 23:45:33] [task-result-getter-0] INFO  TaskSetManager:54 - Finished task 109.0 in stage 0.0 (TID 109) in 69310 ms on himrod-13 (executor 1) (109/1971)
[2019-01-27 23:45:33] [dispatcher-event-loop-5] INFO  TaskSetManager:54 - Starting task 253.0 in stage 0.0 (TID 253, himrod-13, executor 1, partition 253, RACK_LOCAL, 9174 bytes)
[2019-01-27 23:45:33] [task-result-getter-1] INFO  TaskSetManager:54 - Finished task 46.0 in stage 0.0 (TID 46) in 69690 ms on himrod-13 (executor 1) (110/1971)
[2019-01-27 23:45:33] [dispatcher-event-loop-18] INFO  TaskSetManager:54 - Starting task 254.0 in stage 0.0 (TID 254, himrod-14, executor 8, partition 254, RACK_LOCAL, 9174 bytes)
[2019-01-27 23:45:33] [task-result-getter-2] INFO  TaskSetManager:54 - Finished task 43.0 in stage 0.0 (TID 43) in 69752 ms on himrod-14 (executor 8) (111/1971)
[2019-01-27 23:45:33] [dispatcher-event-loop-2] INFO  TaskSetManager:54 - Starting task 255.0 in stage 0.0 (TID 255, himrod-16, executor 2, partition 255, RACK_LOCAL, 9174 bytes)
[2019-01-27 23:45:33] [task-result-getter-3] INFO  TaskSetManager:54 - Finished task 65.0 in stage 0.0 (TID 65) in 69739 ms on himrod-16 (executor 2) (112/1971)
[2019-01-27 23:45:33] [dispatcher-event-loop-13] INFO  TaskSetManager:54 - Starting task 256.0 in stage 0.0 (TID 256, himrod-11, executor 3, partition 256, RACK_LOCAL, 9174 bytes)
[2019-01-27 23:45:33] [task-result-getter-0] INFO  TaskSetManager:54 - Finished task 66.0 in stage 0.0 (TID 66) in 69961 ms on himrod-11 (executor 3) (113/1971)
[2019-01-27 23:45:33] [dispatcher-event-loop-17] INFO  TaskSetManager:54 - Starting task 257.0 in stage 0.0 (TID 257, himrod-14, executor 8, partition 257, RACK_LOCAL, 9174 bytes)
[2019-01-27 23:45:33] [task-result-getter-1] INFO  TaskSetManager:54 - Finished task 133.0 in stage 0.0 (TID 133) in 69924 ms on himrod-14 (executor 8) (114/1971)
[2019-01-27 23:45:33] [dispatcher-event-loop-23] INFO  TaskSetManager:54 - Starting task 258.0 in stage 0.0 (TID 258, himrod-18, executor 9, partition 258, RACK_LOCAL, 9174 bytes)
[2019-01-27 23:45:33] [task-result-getter-2] INFO  TaskSetManager:54 - Finished task 81.0 in stage 0.0 (TID 81) in 70107 ms on himrod-18 (executor 9) (115/1971)
[2019-01-27 23:45:34] [dispatcher-event-loop-22] INFO  TaskSetManager:54 - Starting task 259.0 in stage 0.0 (TID 259, himrod-16, executor 2, partition 259, RACK_LOCAL, 9174 bytes)
[2019-01-27 23:45:34] [task-result-getter-3] INFO  TaskSetManager:54 - Finished task 2.0 in stage 0.0 (TID 2) in 70375 ms on himrod-16 (executor 2) (116/1971)
[2019-01-27 23:45:34] [dispatcher-event-loop-22] INFO  TaskSetManager:54 - Starting task 260.0 in stage 0.0 (TID 260, himrod-17, executor 7, partition 260, RACK_LOCAL, 9174 bytes)
[2019-01-27 23:45:34] [task-result-getter-0] INFO  TaskSetManager:54 - Finished task 112.0 in stage 0.0 (TID 112) in 70252 ms on himrod-17 (executor 7) (117/1971)
[2019-01-27 23:45:34] [dispatcher-event-loop-28] INFO  TaskSetManager:54 - Starting task 261.0 in stage 0.0 (TID 261, himrod-11, executor 3, partition 261, RACK_LOCAL, 9174 bytes)
[2019-01-27 23:45:34] [task-result-getter-1] INFO  TaskSetManager:54 - Finished task 129.0 in stage 0.0 (TID 129) in 70248 ms on himrod-11 (executor 3) (118/1971)
[2019-01-27 23:45:34] [dispatcher-event-loop-6] INFO  TaskSetManager:54 - Starting task 262.0 in stage 0.0 (TID 262, himrod-18, executor 9, partition 262, RACK_LOCAL, 9174 bytes)
[2019-01-27 23:45:34] [task-result-getter-2] INFO  TaskSetManager:54 - Finished task 72.0 in stage 0.0 (TID 72) in 70310 ms on himrod-18 (executor 9) (119/1971)
[2019-01-27 23:45:34] [dispatcher-event-loop-7] INFO  TaskSetManager:54 - Starting task 263.0 in stage 0.0 (TID 263, himrod-15, executor 6, partition 263, RACK_LOCAL, 9174 bytes)
[2019-01-27 23:45:34] [task-result-getter-3] INFO  TaskSetManager:54 - Finished task 26.0 in stage 0.0 (TID 26) in 70440 ms on himrod-15 (executor 6) (120/1971)
[2019-01-27 23:45:34] [dispatcher-event-loop-21] INFO  TaskSetManager:54 - Starting task 264.0 in stage 0.0 (TID 264, himrod-15, executor 6, partition 264, RACK_LOCAL, 9174 bytes)
[2019-01-27 23:45:34] [task-result-getter-0] INFO  TaskSetManager:54 - Finished task 53.0 in stage 0.0 (TID 53) in 70519 ms on himrod-15 (executor 6) (121/1971)
[2019-01-27 23:45:34] [dispatcher-event-loop-10] INFO  TaskSetManager:54 - Starting task 265.0 in stage 0.0 (TID 265, himrod-14, executor 8, partition 265, RACK_LOCAL, 9174 bytes)
[2019-01-27 23:45:34] [task-result-getter-1] INFO  TaskSetManager:54 - Finished task 34.0 in stage 0.0 (TID 34) in 70541 ms on himrod-14 (executor 8) (122/1971)
[2019-01-27 23:45:34] [dispatcher-event-loop-9] INFO  TaskSetManager:54 - Starting task 266.0 in stage 0.0 (TID 266, himrod-15, executor 6, partition 266, RACK_LOCAL, 9174 bytes)
[2019-01-27 23:45:34] [task-result-getter-2] INFO  TaskSetManager:54 - Finished task 35.0 in stage 0.0 (TID 35) in 70703 ms on himrod-15 (executor 6) (123/1971)
[2019-01-27 23:45:34] [dispatcher-event-loop-29] INFO  TaskSetManager:54 - Starting task 267.0 in stage 0.0 (TID 267, himrod-17, executor 7, partition 267, RACK_LOCAL, 9174 bytes)
[2019-01-27 23:45:34] [task-result-getter-3] INFO  TaskSetManager:54 - Finished task 22.0 in stage 0.0 (TID 22) in 70722 ms on himrod-17 (executor 7) (124/1971)
[2019-01-27 23:45:34] [dispatcher-event-loop-12] INFO  TaskSetManager:54 - Starting task 268.0 in stage 0.0 (TID 268, himrod-17, executor 7, partition 268, RACK_LOCAL, 9174 bytes)
[2019-01-27 23:45:34] [task-result-getter-0] INFO  TaskSetManager:54 - Finished task 130.0 in stage 0.0 (TID 130) in 70672 ms on himrod-17 (executor 7) (125/1971)
[2019-01-27 23:45:34] [dispatcher-event-loop-25] INFO  TaskSetManager:54 - Starting task 269.0 in stage 0.0 (TID 269, himrod-17, executor 7, partition 269, RACK_LOCAL, 9174 bytes)
[2019-01-27 23:45:34] [task-result-getter-1] INFO  TaskSetManager:54 - Finished task 121.0 in stage 0.0 (TID 121) in 70716 ms on himrod-17 (executor 7) (126/1971)
[2019-01-27 23:45:34] [dispatcher-event-loop-11] INFO  TaskSetManager:54 - Starting task 270.0 in stage 0.0 (TID 270, himrod-14, executor 8, partition 270, RACK_LOCAL, 9174 bytes)
[2019-01-27 23:45:34] [task-result-getter-2] INFO  TaskSetManager:54 - Finished task 88.0 in stage 0.0 (TID 88) in 70844 ms on himrod-14 (executor 8) (127/1971)
[2019-01-27 23:45:34] [dispatcher-event-loop-15] INFO  TaskSetManager:54 - Starting task 271.0 in stage 0.0 (TID 271, himrod-17, executor 7, partition 271, RACK_LOCAL, 9174 bytes)
[2019-01-27 23:45:34] [task-result-getter-3] INFO  TaskSetManager:54 - Finished task 49.0 in stage 0.0 (TID 49) in 70911 ms on himrod-17 (executor 7) (128/1971)
[2019-01-27 23:45:34] [dispatcher-event-loop-14] INFO  TaskSetManager:54 - Starting task 272.0 in stage 0.0 (TID 272, himrod-17, executor 7, partition 272, RACK_LOCAL, 9174 bytes)
[2019-01-27 23:45:34] [task-result-getter-0] INFO  TaskSetManager:54 - Finished task 4.0 in stage 0.0 (TID 4) in 70988 ms on himrod-17 (executor 7) (129/1971)
[2019-01-27 23:45:34] [dispatcher-event-loop-19] INFO  TaskSetManager:54 - Starting task 273.0 in stage 0.0 (TID 273, himrod-15, executor 6, partition 273, RACK_LOCAL, 9174 bytes)
[2019-01-27 23:45:34] [task-result-getter-1] INFO  TaskSetManager:54 - Finished task 98.0 in stage 0.0 (TID 98) in 71033 ms on himrod-15 (executor 6) (130/1971)
[2019-01-27 23:45:34] [dispatcher-event-loop-16] INFO  TaskSetManager:54 - Starting task 274.0 in stage 0.0 (TID 274, himrod-12, executor 5, partition 274, RACK_LOCAL, 9174 bytes)
[2019-01-27 23:45:34] [task-result-getter-2] INFO  TaskSetManager:54 - Finished task 96.0 in stage 0.0 (TID 96) in 71054 ms on himrod-12 (executor 5) (131/1971)
[2019-01-27 23:45:35] [dispatcher-event-loop-22] INFO  TaskSetManager:54 - Starting task 275.0 in stage 0.0 (TID 275, himrod-19, executor 4, partition 275, RACK_LOCAL, 9174 bytes)
[2019-01-27 23:45:35] [task-result-getter-3] INFO  TaskSetManager:54 - Finished task 104.0 in stage 0.0 (TID 104) in 71272 ms on himrod-19 (executor 4) (132/1971)
[2019-01-27 23:45:35] [dispatcher-event-loop-20] INFO  TaskSetManager:54 - Starting task 276.0 in stage 0.0 (TID 276, himrod-18, executor 9, partition 276, RACK_LOCAL, 9174 bytes)
[2019-01-27 23:45:35] [task-result-getter-0] INFO  TaskSetManager:54 - Finished task 18.0 in stage 0.0 (TID 18) in 71561 ms on himrod-18 (executor 9) (133/1971)
[2019-01-27 23:45:35] [dispatcher-event-loop-4] INFO  TaskSetManager:54 - Starting task 277.0 in stage 0.0 (TID 277, himrod-17, executor 7, partition 277, RACK_LOCAL, 9174 bytes)
[2019-01-27 23:45:35] [task-result-getter-1] INFO  TaskSetManager:54 - Finished task 85.0 in stage 0.0 (TID 85) in 71638 ms on himrod-17 (executor 7) (134/1971)
[2019-01-27 23:45:35] [dispatcher-event-loop-0] INFO  TaskSetManager:54 - Starting task 278.0 in stage 0.0 (TID 278, himrod-14, executor 8, partition 278, RACK_LOCAL, 9174 bytes)
[2019-01-27 23:45:35] [task-result-getter-2] INFO  TaskSetManager:54 - Finished task 97.0 in stage 0.0 (TID 97) in 71715 ms on himrod-14 (executor 8) (135/1971)
[2019-01-27 23:45:35] [dispatcher-event-loop-1] INFO  TaskSetManager:54 - Starting task 279.0 in stage 0.0 (TID 279, himrod-17, executor 7, partition 279, RACK_LOCAL, 9174 bytes)
[2019-01-27 23:45:35] [task-result-getter-3] INFO  TaskSetManager:54 - Finished task 67.0 in stage 0.0 (TID 67) in 71785 ms on himrod-17 (executor 7) (136/1971)
[2019-01-27 23:45:35] [dispatcher-event-loop-10] INFO  TaskSetManager:54 - Starting task 280.0 in stage 0.0 (TID 280, himrod-13, executor 1, partition 280, RACK_LOCAL, 9174 bytes)
[2019-01-27 23:45:35] [task-result-getter-0] INFO  TaskSetManager:54 - Finished task 136.0 in stage 0.0 (TID 136) in 71739 ms on himrod-13 (executor 1) (137/1971)
[2019-01-27 23:45:35] [dispatcher-event-loop-26] INFO  TaskSetManager:54 - Starting task 281.0 in stage 0.0 (TID 281, himrod-11, executor 3, partition 281, RACK_LOCAL, 9174 bytes)
[2019-01-27 23:45:35] [task-result-getter-1] INFO  TaskSetManager:54 - Finished task 12.0 in stage 0.0 (TID 12) in 71934 ms on himrod-11 (executor 3) (138/1971)
[2019-01-27 23:45:35] [dispatcher-event-loop-29] INFO  TaskSetManager:54 - Starting task 282.0 in stage 0.0 (TID 282, himrod-17, executor 7, partition 282, RACK_LOCAL, 9174 bytes)
[2019-01-27 23:45:35] [task-result-getter-2] INFO  TaskSetManager:54 - Finished task 31.0 in stage 0.0 (TID 31) in 72024 ms on himrod-17 (executor 7) (139/1971)
[2019-01-27 23:45:35] [dispatcher-event-loop-31] INFO  TaskSetManager:54 - Starting task 283.0 in stage 0.0 (TID 283, himrod-19, executor 4, partition 283, RACK_LOCAL, 9174 bytes)
[2019-01-27 23:45:35] [task-result-getter-3] INFO  TaskSetManager:54 - Finished task 131.0 in stage 0.0 (TID 131) in 71982 ms on himrod-19 (executor 4) (140/1971)
[2019-01-27 23:45:35] [dispatcher-event-loop-5] INFO  TaskSetManager:54 - Starting task 284.0 in stage 0.0 (TID 284, himrod-13, executor 1, partition 284, RACK_LOCAL, 9174 bytes)
[2019-01-27 23:45:35] [task-result-getter-0] INFO  TaskSetManager:54 - Finished task 19.0 in stage 0.0 (TID 19) in 72195 ms on himrod-13 (executor 1) (141/1971)
[2019-01-27 23:45:36] [dispatcher-event-loop-11] INFO  TaskSetManager:54 - Starting task 285.0 in stage 0.0 (TID 285, himrod-18, executor 9, partition 285, RACK_LOCAL, 9174 bytes)
[2019-01-27 23:45:36] [task-result-getter-1] INFO  TaskSetManager:54 - Finished task 9.0 in stage 0.0 (TID 9) in 72473 ms on himrod-18 (executor 9) (142/1971)
[2019-01-27 23:45:36] [dispatcher-event-loop-15] INFO  TaskSetManager:54 - Starting task 286.0 in stage 0.0 (TID 286, himrod-13, executor 1, partition 286, RACK_LOCAL, 9174 bytes)
[2019-01-27 23:45:36] [task-result-getter-2] INFO  TaskSetManager:54 - Finished task 118.0 in stage 0.0 (TID 118) in 72367 ms on himrod-13 (executor 1) (143/1971)
[2019-01-27 23:45:41] [dispatcher-event-loop-27] INFO  TaskSetManager:54 - Starting task 287.0 in stage 0.0 (TID 287, himrod-15, executor 6, partition 287, RACK_LOCAL, 9174 bytes)
[2019-01-27 23:45:41] [task-result-getter-3] INFO  TaskSetManager:54 - Finished task 89.0 in stage 0.0 (TID 89) in 77340 ms on himrod-15 (executor 6) (144/1971)
[2019-01-27 23:46:10] [dispatcher-event-loop-27] INFO  TaskSetManager:54 - Starting task 288.0 in stage 0.0 (TID 288, himrod-11, executor 3, partition 288, RACK_LOCAL, 9174 bytes)
[2019-01-27 23:46:10] [task-result-getter-0] INFO  TaskSetManager:54 - Finished task 147.0 in stage 0.0 (TID 147) in 44418 ms on himrod-11 (executor 3) (145/1971)
[2019-01-27 23:46:11] [dispatcher-event-loop-30] INFO  TaskSetManager:54 - Starting task 289.0 in stage 0.0 (TID 289, himrod-17, executor 7, partition 289, RACK_LOCAL, 9174 bytes)
[2019-01-27 23:46:11] [task-result-getter-1] INFO  TaskSetManager:54 - Finished task 231.0 in stage 0.0 (TID 231) in 39647 ms on himrod-17 (executor 7) (146/1971)
[2019-01-27 23:46:11] [dispatcher-event-loop-28] INFO  TaskSetManager:54 - Starting task 290.0 in stage 0.0 (TID 290, himrod-13, executor 1, partition 290, RACK_LOCAL, 9174 bytes)
[2019-01-27 23:46:11] [task-result-getter-2] INFO  TaskSetManager:54 - Finished task 220.0 in stage 0.0 (TID 220) in 40907 ms on himrod-13 (executor 1) (147/1971)
[2019-01-27 23:46:11] [dispatcher-event-loop-6] INFO  TaskSetManager:54 - Starting task 291.0 in stage 0.0 (TID 291, himrod-13, executor 1, partition 291, RACK_LOCAL, 9174 bytes)
[2019-01-27 23:46:11] [task-result-getter-3] INFO  TaskSetManager:54 - Finished task 229.0 in stage 0.0 (TID 229) in 40203 ms on himrod-13 (executor 1) (148/1971)
[2019-01-27 23:46:11] [dispatcher-event-loop-7] INFO  TaskSetManager:54 - Starting task 292.0 in stage 0.0 (TID 292, himrod-19, executor 4, partition 292, RACK_LOCAL, 9174 bytes)
[2019-01-27 23:46:11] [task-result-getter-0] INFO  TaskSetManager:54 - Finished task 221.0 in stage 0.0 (TID 221) in 40948 ms on himrod-19 (executor 4) (149/1971)
[2019-01-27 23:46:11] [dispatcher-event-loop-21] INFO  TaskSetManager:54 - Starting task 293.0 in stage 0.0 (TID 293, himrod-15, executor 6, partition 293, RACK_LOCAL, 9174 bytes)
[2019-01-27 23:46:11] [task-result-getter-1] INFO  TaskSetManager:54 - Finished task 224.0 in stage 0.0 (TID 224) in 40952 ms on himrod-15 (executor 6) (150/1971)
[2019-01-27 23:46:11] [dispatcher-event-loop-8] INFO  TaskSetManager:54 - Starting task 294.0 in stage 0.0 (TID 294, himrod-13, executor 1, partition 294, RACK_LOCAL, 9174 bytes)
[2019-01-27 23:46:11] [task-result-getter-2] INFO  TaskSetManager:54 - Finished task 226.0 in stage 0.0 (TID 226) in 40914 ms on himrod-13 (executor 1) (151/1971)
[2019-01-27 23:46:11] [dispatcher-event-loop-9] INFO  TaskSetManager:54 - Starting task 295.0 in stage 0.0 (TID 295, himrod-17, executor 7, partition 295, RACK_LOCAL, 9174 bytes)
[2019-01-27 23:46:11] [task-result-getter-3] INFO  TaskSetManager:54 - Finished task 227.0 in stage 0.0 (TID 227) in 40934 ms on himrod-17 (executor 7) (152/1971)
